<!--URDF generated by ONSHAPE BY PTC INC, 1.213-->
<robot name="assembly">
    <link name="base">
        <inertial>
            <mass value="0.02496" />
            <origin xyz="3.38813e-18 3.25782e-18 -0.46" rpy="0 -0 0" />
            <inertia ixx="0.00136115" ixy="0" ixz="0" iyy="0.00147181" iyz="0" izz="0.00017056" />
        </inertial>
        <visual>
            <origin xyz="0 0 0" rpy="0 -0 0" />
            <geometry>
                <mesh filename="package://assembly/meshes/Base.stl" scale="1 1 1" />
            </geometry>
            <material name="0.647059_0.647059_0.647059_0.000000_0.000000">
                <texture />
                <color rgba="0.647059 0.647059 0.647059 1" />
            </material>
        </visual>
        <collision>
            <origin xyz="0 0 0" rpy="0 -0 0" />
            <geometry>
                <mesh filename="package://assembly/meshes/Base.stl" scale="1 1 1" />
            </geometry>
        </collision>
    </link>
    <link name="left_e1">
        <inertial>
            <mass value="0.00207775" />
            <origin xyz="8.32667e-17 0.00286547 -0.164964" rpy="0 -0 0" />
            <inertia ixx="2.29869e-05" ixy="0" ixz="0" iyy="2.30859e-05" iyz="1.84549e-07" izz="2.37836e-06" />
        </inertial>
        <visual>
            <origin xyz="-0.19958 2.34488e-17 0.07335" rpy="0 -0 0" />
            <geometry>
                <mesh filename="package://assembly/meshes/Left_E1.stl" scale="1 1 1" />
            </geometry>
            <material name="0.917647_0.917647_0.917647_0.000000_0.000000">
                <texture />
                <color rgba="0.917647 0.917647 0.917647 1" />
            </material>
        </visual>
        <collision>
            <origin xyz="-0.19958 2.34488e-17 0.07335" rpy="0 -0 0" />
            <geometry>
                <mesh filename="package://assembly/meshes/Left_E1.stl" scale="1 1 1" />
            </geometry>
        </collision>
    </link>
    <link name="left_e2">
        <inertial>
            <mass value="0.000814328" />
            <origin xyz="-0.024782 1.16059e-18 -0.073009" rpy="0 -0 0" />
            <inertia ixx="1.64792e-06" ixy="0" ixz="-4.00388e-07" iyy="1.98055e-06" iyz="0" izz="1.32317e-06" />
        </inertial>
        <visual>
            <origin xyz="-0.24187 0 0.362735" rpy="0 -0 0" />
            <geometry>
                <mesh filename="package://assembly/meshes/Left_E2.stl" scale="1 1 1" />
            </geometry>
            <material name="0.768627_0.886275_0.952941_0.000000_0.000000">
                <texture />
                <color rgba="0.768627 0.886275 0.952941 1" />
            </material>
        </visual>
        <collision>
            <origin xyz="-0.24187 0 0.362735" rpy="0 -0 0" />
            <geometry>
                <mesh filename="package://assembly/meshes/Left_E2.stl" scale="1 1 1" />
            </geometry>
        </collision>
    </link>
    <link name="left_gripper">
        <inertial>
            <mass value="0.00016575" />
            <origin xyz="-2.77556e-17 1.27758e-18 -0.0257466" rpy="0 -0 0" />
            <inertia ixx="7.59701e-08" ixy="0" ixz="0" iyy="9.23262e-08" iyz="0" izz="8.54186e-08" />
        </inertial>
        <visual>
            <origin xyz="-0.19958 0 0.713195" rpy="0 -0 0" />
            <geometry>
                <mesh filename="package://assembly/meshes/Left Gripper.stl" scale="1 1 1" />
            </geometry>
            <material name="0.615686_0.811765_0.929412_0.000000_0.000000">
                <texture />
                <color rgba="0.615686 0.811765 0.929412 1" />
            </material>
        </visual>
        <collision>
            <origin xyz="-0.19958 0 0.713195" rpy="0 -0 0" />
            <geometry>
                <mesh filename="package://assembly/meshes/Left Gripper.stl" scale="1 1 1" />
            </geometry>
        </collision>
    </link>
    <link name="left_s2">
        <inertial>
            <mass value="0.00108759" />
            <origin xyz="0.0652231 1.83545e-17 3.47553e-16" rpy="0 -0 0" />
            <inertia ixx="1.66993e-06" ixy="0" ixz="0" iyy="2.13356e-06" iyz="0" izz="1.91562e-06" />
        </inertial>
        <visual>
            <origin xyz="-0.13 1.83545e-17 -4.58863e-18" rpy="0 -0 0" />
            <geometry>
                <mesh filename="package://assembly/meshes/Left_S2.stl" scale="1 1 1" />
            </geometry>
            <material name="0.647059_0.647059_0.647059_0.000000_0.000000">
                <texture />
                <color rgba="0.647059 0.647059 0.647059 1" />
            </material>
        </visual>
        <collision>
            <origin xyz="-0.13 1.83545e-17 -4.58863e-18" rpy="0 -0 0" />
            <geometry>
                <mesh filename="package://assembly/meshes/Left_S2.stl" scale="1 1 1" />
            </geometry>
        </collision>
    </link>
    <link name="left_s3">
        <inertial>
            <mass value="0.000265068" />
            <origin xyz="5.38752e-11 0.0115864 -0.0302711" rpy="0 -0 0" />
            <inertia ixx="5.7914e-07" ixy="0" ixz="0" iyy="6.01092e-07" iyz="1.60044e-07" izz="3.7865e-07" />
        </inertial>
        <visual>
            <origin xyz="-0.19958 0.04475 -3.81639e-16" rpy="0 -0 0" />
            <geometry>
                <mesh filename="package://assembly/meshes/Left_S3.stl" scale="1 1 1" />
            </geometry>
            <material name="0.231373_0.380392_0.705882_0.000000_0.000000">
                <texture />
                <color rgba="0.231373 0.380392 0.705882 1" />
            </material>
        </visual>
        <collision>
            <origin xyz="-0.19958 0.04475 -3.81639e-16" rpy="0 -0 0" />
            <geometry>
                <mesh filename="package://assembly/meshes/Left_S3.stl" scale="1 1 1" />
            </geometry>
        </collision>
    </link>
    <link name="left_w0">
        <inertial>
            <mass value="0.0005018" />
            <origin xyz="8.32667e-17 2.10999e-18 -0.0614121" rpy="0 -0 0" />
            <inertia ixx="9.85808e-07" ixy="0" ixz="0" iyy="8.60117e-07" iyz="0" izz="3.9447e-07" />
        </inertial>
        <visual>
            <origin xyz="-0.19958 0 0.487025" rpy="0 -0 0" />
            <geometry>
                <mesh filename="package://assembly/meshes/Left_W0.stl" scale="1 1 1" />
            </geometry>
            <material name="0.972549_0.529412_0.003922_0.000000_0.000000">
                <texture />
                <color rgba="0.972549 0.529412 0.00392157 1" />
            </material>
        </visual>
        <collision>
            <origin xyz="-0.19958 0 0.487025" rpy="0 -0 0" />
            <geometry>
                <mesh filename="package://assembly/meshes/Left_W0.stl" scale="1 1 1" />
            </geometry>
        </collision>
    </link>
    <link name="left_w1">
        <inertial>
            <mass value="0.000330643" />
            <origin xyz="1.38778e-16 0.0285 -0.0285" rpy="0 -0 0" />
            <inertia ixx="3.827e-07" ixy="0" ixz="0" iyy="3.827e-07" iyz="0" izz="1.69198e-07" />
        </inertial>
        <visual>
            <origin xyz="-0.19958 0.0285 0.622695" rpy="0 -0 0" />
            <geometry>
                <mesh filename="package://assembly/meshes/Left_W1.stl" scale="1 1 1" />
            </geometry>
            <material name="0.498039_0.498039_0.498039_0.000000_0.000000">
                <texture />
                <color rgba="0.498039 0.498039 0.498039 1" />
            </material>
        </visual>
        <collision>
            <origin xyz="-0.19958 0.0285 0.622695" rpy="0 -0 0" />
            <geometry>
                <mesh filename="package://assembly/meshes/Left_W1.stl" scale="1 1 1" />
            </geometry>
        </collision>
    </link>
    <link name="left_w2">
        <inertial>
            <mass value="4.80988e-05" />
            <origin xyz="0.0285 6.89855e-18 -0.0139111" rpy="0 -0 0" />
            <inertia ixx="2.82303e-08" ixy="0" ixz="0" iyy="5.11474e-08" iyz="0" izz="4.72353e-08" />
        </inertial>
        <visual>
            <origin xyz="-0.17108 0 0.679695" rpy="0 -0 0" />
            <geometry>
                <mesh filename="package://assembly/meshes/Left_W2.stl" scale="1 1 1" />
            </geometry>
            <material name="0.980392_0.713725_0.003922_0.000000_0.000000">
                <texture />
                <color rgba="0.980392 0.713726 0.00392157 1" />
            </material>
        </visual>
        <collision>
            <origin xyz="-0.17108 0 0.679695" rpy="0 -0 0" />
            <geometry>
                <mesh filename="package://assembly/meshes/Left_W2.stl" scale="1 1 1" />
            </geometry>
        </collision>
    </link>
    <link name="right_e1">
        <inertial>
            <mass value="0.00207775" />
            <origin xyz="-8.32667e-17 0.00286547 -0.164964" rpy="0 -0 0" />
            <inertia ixx="2.29869e-05" ixy="0" ixz="0" iyy="2.30859e-05" iyz="1.84549e-07" izz="2.37836e-06" />
        </inertial>
        <visual>
            <origin xyz="0.19958 2.34488e-17 0.07335" rpy="0 -0 0" />
            <geometry>
                <mesh filename="package://assembly/meshes/Right_E1.stl" scale="1 1 1" />
            </geometry>
            <material name="0.917647_0.917647_0.917647_0.000000_0.000000">
                <texture />
                <color rgba="0.917647 0.917647 0.917647 1" />
            </material>
        </visual>
        <collision>
            <origin xyz="0.19958 2.34488e-17 0.07335" rpy="0 -0 0" />
            <geometry>
                <mesh filename="package://assembly/meshes/Right_E1.stl" scale="1 1 1" />
            </geometry>
        </collision>
    </link>
    <link name="right_e2">
        <inertial>
            <mass value="0.000814328" />
            <origin xyz="0.024782 9.19732e-19 -0.073009" rpy="0 -0 0" />
            <inertia ixx="1.64792e-06" ixy="0" ixz="4.00388e-07" iyy="1.98055e-06" iyz="0" izz="1.32317e-06" />
        </inertial>
        <visual>
            <origin xyz="0.24187 0 0.362735" rpy="0 -0 0" />
            <geometry>
                <mesh filename="package://assembly/meshes/Right_E2.stl" scale="1 1 1" />
            </geometry>
            <material name="0.768627_0.886275_0.952941_0.000000_0.000000">
                <texture />
                <color rgba="0.768627 0.886275 0.952941 1" />
            </material>
        </visual>
        <collision>
            <origin xyz="0.24187 0 0.362735" rpy="0 -0 0" />
            <geometry>
                <mesh filename="package://assembly/meshes/Right_E2.stl" scale="1 1 1" />
            </geometry>
        </collision>
    </link>
    <link name="right_gripper">
        <inertial>
            <mass value="0.00016575" />
            <origin xyz="2.77556e-17 2.55515e-18 -0.0257466" rpy="0 -0 0" />
            <inertia ixx="7.59701e-08" ixy="0" ixz="0" iyy="9.23262e-08" iyz="0" izz="8.54186e-08" />
        </inertial>
        <visual>
            <origin xyz="0.19958 0 0.713195" rpy="0 -0 0" />
            <geometry>
                <mesh filename="package://assembly/meshes/Right Gripper.stl" scale="1 1 1" />
            </geometry>
            <material name="0.615686_0.811765_0.929412_0.000000_0.000000">
                <texture />
                <color rgba="0.615686 0.811765 0.929412 1" />
            </material>
        </visual>
        <collision>
            <origin xyz="0.19958 0 0.713195" rpy="0 -0 0" />
            <geometry>
                <mesh filename="package://assembly/meshes/Right Gripper.stl" scale="1 1 1" />
            </geometry>
        </collision>
    </link>
    <link name="right_s2">
        <inertial>
            <mass value="0.00108759" />
            <origin xyz="-0.0652231 2.14698e-17 3.48478e-16" rpy="0 -0 0" />
            <inertia ixx="1.66993e-06" ixy="0" ixz="0" iyy="2.13356e-06" iyz="0" izz="1.91562e-06" />
        </inertial>
        <visual>
            <origin xyz="0.13 1.83545e-17 -4.58863e-18" rpy="0 -0 0" />
            <geometry>
                <mesh filename="package://assembly/meshes/Right_S2.stl" scale="1 1 1" />
            </geometry>
            <material name="0.647059_0.647059_0.647059_0.000000_0.000000">
                <texture />
                <color rgba="0.647059 0.647059 0.647059 1" />
            </material>
        </visual>
        <collision>
            <origin xyz="0.13 1.83545e-17 -4.58863e-18" rpy="0 -0 0" />
            <geometry>
                <mesh filename="package://assembly/meshes/Right_S2.stl" scale="1 1 1" />
            </geometry>
        </collision>
    </link>
    <link name="right_s3">
        <inertial>
            <mass value="0.000265068" />
            <origin xyz="-8.34369e-11 0.0115864 -0.0302711" rpy="0 -0 0" />
            <inertia ixx="5.7914e-07" ixy="1.34483e-15" ixz="0" iyy="6.01092e-07" iyz="1.60044e-07" izz="3.7865e-07" />
        </inertial>
        <visual>
            <origin xyz="0.19958 0.04475 -3.81639e-16" rpy="0 -0 0" />
            <geometry>
                <mesh filename="package://assembly/meshes/Right_S3.stl" scale="1 1 1" />
            </geometry>
            <material name="0.231373_0.380392_0.705882_0.000000_0.000000">
                <texture />
                <color rgba="0.231373 0.380392 0.705882 1" />
            </material>
        </visual>
        <collision>
            <origin xyz="0.19958 0.04475 -3.81639e-16" rpy="0 -0 0" />
            <geometry>
                <mesh filename="package://assembly/meshes/Right_S3.stl" scale="1 1 1" />
            </geometry>
        </collision>
    </link>
    <link name="right_w0">
        <inertial>
            <mass value="0.0005018" />
            <origin xyz="-8.32667e-17 1.05499e-18 -0.0614121" rpy="0 -0 0" />
            <inertia ixx="9.85808e-07" ixy="0" ixz="0" iyy="8.60117e-07" iyz="0" izz="3.9447e-07" />
        </inertial>
        <visual>
            <origin xyz="0.19958 0 0.487025" rpy="0 -0 0" />
            <geometry>
                <mesh filename="package://assembly/meshes/Right_W0.stl" scale="1 1 1" />
            </geometry>
            <material name="0.972549_0.529412_0.003922_0.000000_0.000000">
                <texture />
                <color rgba="0.972549 0.529412 0.00392157 1" />
            </material>
        </visual>
        <collision>
            <origin xyz="0.19958 0 0.487025" rpy="0 -0 0" />
            <geometry>
                <mesh filename="package://assembly/meshes/Right_W0.stl" scale="1 1 1" />
            </geometry>
        </collision>
    </link>
    <link name="right_w1">
        <inertial>
            <mass value="0.000330643" />
            <origin xyz="-1.38778e-16 0.0285 -0.0285" rpy="0 -0 0" />
            <inertia ixx="3.827e-07" ixy="0" ixz="0" iyy="3.827e-07" iyz="0" izz="1.69198e-07" />
        </inertial>
        <visual>
            <origin xyz="0.19958 0.0285 0.622695" rpy="0 -0 0" />
            <geometry>
                <mesh filename="package://assembly/meshes/Right_W1.stl" scale="1 1 1" />
            </geometry>
            <material name="0.498039_0.498039_0.498039_0.000000_0.000000">
                <texture />
                <color rgba="0.498039 0.498039 0.498039 1" />
            </material>
        </visual>
        <collision>
            <origin xyz="0.19958 0.0285 0.622695" rpy="0 -0 0" />
            <geometry>
                <mesh filename="package://assembly/meshes/Right_W1.stl" scale="1 1 1" />
            </geometry>
        </collision>
    </link>
    <link name="right_w2">
        <inertial>
            <mass value="4.80988e-05" />
            <origin xyz="-0.0285 6.30915e-18 -0.0139111" rpy="0 -0 0" />
            <inertia ixx="2.82303e-08" ixy="0" ixz="0" iyy="5.11474e-08" iyz="0" izz="4.72353e-08" />
        </inertial>
        <visual>
            <origin xyz="0.17108 0 0.679695" rpy="0 -0 0" />
            <geometry>
                <mesh filename="package://assembly/meshes/Right_W2.stl" scale="1 1 1" />
            </geometry>
            <material name="0.980392_0.713725_0.003922_0.000000_0.000000">
                <texture />
                <color rgba="0.980392 0.713726 0.00392157 1" />
            </material>
        </visual>
        <collision>
            <origin xyz="0.17108 0 0.679695" rpy="0 -0 0" />
            <geometry>
                <mesh filename="package://assembly/meshes/Right_W2.stl" scale="1 1 1" />
            </geometry>
        </collision>
    </link>
    <link name="root" />
    <link name="s1">
        <inertial>
            <mass value="0.003744" />
            <origin xyz="1.48412e-17 1.8099e-18 0.06" rpy="0 -0 0" />
            <inertia ixx="8.9856e-06" ixy="0" ixz="0" iyy="2.5584e-05" iyz="0" izz="2.5584e-05" />
        </inertial>
        <visual>
            <origin xyz="2.78001e-17 0 0.06" rpy="0 -0 0" />
            <geometry>
                <mesh filename="package://assembly/meshes/S1.stl" scale="1 1 1" />
            </geometry>
            <material name="0.615686_0.811765_0.929412_0.000000_0.000000">
                <texture />
                <color rgba="0.615686 0.811765 0.929412 1" />
            </material>
        </visual>
        <collision>
            <origin xyz="2.78001e-17 0 0.06" rpy="0 -0 0" />
            <geometry>
                <mesh filename="package://assembly/meshes/S1.stl" scale="1 1 1" />
            </geometry>
        </collision>
    </link>
    <joint name="base_0" type="fixed">
        <origin xyz="-2.79001e-17 6.93889e-18 -0.06" rpy="0 -1.06752e-16 0" />
        <axis xyz="1.06752e-16 0 1" />
        <parent link="base" />
        <child link="s1" />
    </joint>
    <joint name="fixed_node_to_root_joint_0" type="fixed">
        <origin xyz="-2.77556e-17 -6.93889e-18 0.86" rpy="0 -0 0" />
        <axis xyz="0 0 1" />
        <parent link="root" />
        <child link="base" />
    </joint>
    <joint name="left_e1_0" type="revolute">
        <origin xyz="0.04229 1.38514e-17 -0.289385" rpy="-8.89879e-17 3.99879e-31 1.22465e-16" />
        <axis xyz="-1 0 2.98117e-16" />
        <parent link="left_e1" />
        <child link="left_e2" />
        <limit lower="0.0" upper="2.6389" velocity="30.0" effort="87.0" />
    </joint>
    <joint name="left_e2_0" type="revolute">
        <origin xyz="-0.03229 -1.38642e-17 -0.12429" rpy="1.6148e-14 2.26208e-15 6.65562e-15" />
        <axis xyz="0 0 1" />
        <parent link="left_e2" />
        <child link="left_w0" />
        <limit lower="-1.5708" upper="1.5708" velocity="30.0" effort="87.0" />
    </joint>
    <joint name="left_gripper_0" type="fixed">
        <origin xyz="0.0285 -6.93889e-18 -0.0335" rpy="0 -0 0" />
        <axis xyz="0 0 -1" />
        <parent link="left_w2" />
        <child link="left_gripper" />
    </joint>
    <joint name="left_s1_0" type="revolute">
        <origin xyz="0.13 2.46349e-18 0.06" rpy="-4.76619e-36 -1.02798e-15 1.03524e-20" />
        <axis xyz="-1 0 0" />
        <parent link="s1" />
        <child link="left_s2" />
        <limit lower="-1.5708" upper="1.5708" velocity="30.0" effort="87.0" />
    </joint>
    <joint name="left_s2_0" type="revolute">
        <origin xyz="0.06958 -0.04475 4.44089e-16" rpy="-1.11022e-16 -1.72409e-15 -2.28994e-16" />
        <axis xyz="0 1 0" />
        <parent link="left_s2" />
        <child link="left_s3" />
        <limit lower="-1.5708" upper="0.1885" velocity="30.0" effort="87.0" />
    </joint>
    <joint name="left_s3_0" type="revolute">
        <origin xyz="-3.88578e-16 0.04475 -0.07335" rpy="6.12323e-17 -8.04912e-16 -3.52374e-15" />
        <axis xyz="0 0 1" />
        <parent link="left_s3" />
        <child link="left_e1" />
        <limit lower="-1.5708" upper="1.5708" velocity="30.0" effort="87.0" />
    </joint>
    <joint name="left_w1_0" type="revolute">
        <origin xyz="-5.55112e-17 -0.0285 -0.13567" rpy="1.57652e-14 -1.23165e-16 1.11994e-14" />
        <axis xyz="0 -1 0" />
        <parent link="left_w0" />
        <child link="left_w1" />
        <limit lower="-1.5708" upper="1.5708" velocity="30.0" effort="87.0" />
    </joint>
    <joint name="left_w2_0" type="revolute">
        <origin xyz="-0.0285 0.0285 -0.057" rpy="-3.36618e-14 -2.11528e-30 -6.12323e-17" />
        <axis xyz="1 0 0" />
        <parent link="left_w1" />
        <child link="left_w2" />
        <limit lower="-1.5708" upper="1.5708" velocity="30.0" effort="87.0" />
    </joint>
    <joint name="right_e1_0" type="revolute">
        <origin xyz="-0.04229 1.9082e-17 -0.289385" rpy="-1.09476e-47 7.39557e-32 1.2326e-32" />
        <axis xyz="1 0 2.98117e-16" />
        <parent link="right_e1" />
        <child link="right_e2" />
        <limit lower="-2.6389" upper="0.0" velocity="30.0" effort="87.0" />
    </joint>
    <joint name="right_e2_0" type="revolute">
        <origin xyz="0.03229 -6.93889e-18 -0.12429" rpy="3.03858e-64 4.93038e-32 1.2326e-32" />
        <axis xyz="0 0 1" />
        <parent link="right_e2" />
        <child link="right_w0" />
        <limit lower="-1.5708" upper="1.5708" velocity="30.0" effort="87.0" />
    </joint>
    <joint name="right_gripper_0" type="fixed">
        <origin xyz="-0.0285 -6.93889e-18 -0.0335" rpy="3.03858e-64 4.93038e-32 1.2326e-32" />
        <axis xyz="0 0 1" />
        <parent link="right_w2" />
        <child link="right_gripper" />
    </joint>
    <joint name="right_s1_0" type="revolute">
        <origin xyz="-0.13 2.46215e-18 0.06" rpy="-4.76873e-49 -2.31296e-16 7.65788e-33" />
        <axis xyz="1 0 0" />
        <parent link="s1" />
        <child link="right_s2" />
        <limit lower="-1.5708" upper="1.5708" velocity="30.0" effort="87.0" />
    </joint>
    <joint name="right_s2_0" type="revolute">
        <origin xyz="-0.06958 -0.04475 4.44089e-16" rpy="-1.28654e-32 -9.17877e-18 -7.824e-17" />
        <axis xyz="0 1 0" />
        <parent link="right_s2" />
        <child link="right_s3" />
        <limit lower="-0.1885" upper="1.5708" velocity="30.0" effort="87.0" />
    </joint>
    <joint name="right_s3_0" type="revolute">
        <origin xyz="3.88578e-16 0.0323582 -0.07335" rpy="-2.73691e-48 4.93038e-32 4.71657e-48" />
        <axis xyz="0 0 1" />
        <parent link="right_s3" />
        <child link="right_e1" />
        <limit lower="-1.5708" upper="1.5708" velocity="30.0" effort="87.0" />
    </joint>
    <joint name="right_w1_0" type="revolute">
        <origin xyz="5.55112e-17 -0.0285 -0.13301" rpy="3.03858e-64 4.93038e-32 1.2326e-32" />
        <axis xyz="0 -1 0" />
        <parent link="right_w0" />
        <child link="right_w1" />
        <limit lower="-1.5708" upper="1.5708" velocity="30.0" effort="87.0" />
    </joint>
    <joint name="right_w2_0" type="revolute">
        <origin xyz="0.0285 0.0285 -0.057" rpy="3.03858e-64 4.93038e-32 1.2326e-32" />
        <axis xyz="-1 0 0" />
        <parent link="right_w1" />
        <child link="right_w2" />
        <limit lower="-1.5708" upper="1.5708" velocity="30.0" effort="87.0" />
    </joint>
</robot>
