<!--URDF generated by ONSHAPE BY PTC INC; adapted for almond_axol (see kinematics/urdf).-->
<robot name="axol_kit">
    <link name="_zed_x_502__zed_x_50_lch_asm_din_en_iso7045_m2x5_4_8h_v1">
        <inertial>
            <mass value="3.02996e-08" />
            <origin xyz="-4.72976e-20 4.90915e-19 0.00257364" rpy="0 -0 0" />
            <inertia ixx="1e-9" ixy="0" ixz="0" iyy="1e-9" iyz="0" izz="1e-9" />
        </inertial>
        <visual>
            <origin xyz="0 0 0" rpy="0 -0 0" />
            <geometry>
                <mesh filename="package://axol_kit/meshes/_ZED_X_502__ZED_X_50_LCH_asm_din_en_iso7045_m2x5_4_8h_v1.stl" scale="1 1 1" />
            </geometry>
            <material name="0.600000_0.600000_0.600000_0.000000_0.000000">
                <color rgba="0.6 0.6 0.6 1" />
            </material>
        </visual>
    </link>
    <link name="_zed_x_502__zed_x_50_lch_asm_din_en_iso7045_m2x5_4_8h_v1_1">
        <inertial>
            <mass value="3.02996e-08" />
            <origin xyz="-4.72976e-20 4.90915e-19 0.00257364" rpy="0 -0 0" />
            <inertia ixx="1e-9" ixy="0" ixz="0" iyy="1e-9" iyz="0" izz="1e-9" />
        </inertial>
        <visual>
            <origin xyz="0 0 0" rpy="0 -0 0" />
            <geometry>
                <mesh filename="package://axol_kit/meshes/_ZED_X_502__ZED_X_50_LCH_asm_din_en_iso7045_m2x5_4_8h_v1.stl" scale="1 1 1" />
            </geometry>
            <material name="0.600000_0.600000_0.600000_0.000000_0.000000">
                <color rgba="0.6 0.6 0.6 1" />
            </material>
        </visual>
    </link>
    <link name="_zedx_mini_rev2__lower_case_v13">
        <inertial>
            <mass value="9.89911e-06" />
            <origin xyz="0.0185002 0.00802489 -0.00224107" rpy="0 -0 0" />
            <inertia ixx="6.95686e-10" ixy="-1.46678e-14" ixz="0" iyy="6.8515e-09" iyz="-5.45067e-12" izz="7.51912e-09" />
        </inertial>
        <visual>
            <origin xyz="0.00591595 -0.00173896 -0.00564672" rpy="0 -0 0" />
            <geometry>
                <mesh filename="package://axol_kit/meshes/_ZEDX_Mini_rev2__Lower_Case_v13.stl" scale="1 1 1" />
            </geometry>
            <material name="0.600000_0.600000_0.600000_0.000000_0.000000">
                <color rgba="0.6 0.6 0.6 1" />
            </material>
        </visual>
    </link>
    <link name="_zedx_mini_rev2__plastron_v2">
        <inertial>
            <mass value="1.3956e-06" />
            <origin xyz="0.0126057 0.00923906 -0.0300235" rpy="0 -0 0" />
            <inertia ixx="9.03655e-11" ixy="0" ixz="0" iyy="7.82025e-10" iyz="0" izz="8.72157e-10" />
        </inertial>
        <visual>
            <origin xyz="0 0 0" rpy="0 -0 0" />
            <geometry>
                <mesh filename="package://axol_kit/meshes/_ZEDX_Mini_rev2__Plastron_v2.stl" scale="1 1 1" />
            </geometry>
            <material name="0.623529_0.666667_0.701961_0.000000_0.000000">
                <color rgba="0.623529 0.666667 0.701961 1" />
            </material>
        </visual>
    </link>
    <link name="_zedx_mini_rev2__plastron_v2_1">
        <inertial>
            <mass value="3.81516e-07" />
            <origin xyz="-0.012416 0.00923896 -0.0300233" rpy="0 -0 0" />
            <inertia ixx="1.16147e-11" ixy="0" ixz="0" iyy="1.16147e-11" iyz="0" izz="2.31657e-11" />
        </inertial>
        <visual>
            <origin xyz="0 0 0" rpy="0 -0 0" />
            <geometry>
                <mesh filename="package://axol_kit/meshes/_ZEDX_Mini_rev2__Plastron_v2_1.stl" scale="1 1 1" />
            </geometry>
            <material name="0.623529_0.666667_0.701961_0.000000_0.000000">
                <color rgba="0.623529 0.666667 0.701961 1" />
            </material>
        </visual>
    </link>
    <link name="_zedx_mini_rev2__plastron_v2_2">
        <inertial>
            <mass value="3.81516e-07" />
            <origin xyz="0.0375727 0.00923896 -0.0300233" rpy="0 -0 0" />
            <inertia ixx="1.16147e-11" ixy="0" ixz="0" iyy="1.16147e-11" iyz="0" izz="2.31657e-11" />
        </inertial>
        <visual>
            <origin xyz="0 0 0" rpy="0 -0 0" />
            <geometry>
                <mesh filename="package://axol_kit/meshes/_ZEDX_Mini_rev2__Plastron_v2_2.stl" scale="1 1 1" />
            </geometry>
            <material name="0.623529_0.666667_0.701961_0.000000_0.000000">
                <color rgba="0.623529 0.666667 0.701961 1" />
            </material>
        </visual>
    </link>
    <link name="_zedx_mini_rev2__upper_case_v8">
        <inertial>
            <mass value="8.68124e-05" />
            <origin xyz="0.012584 0.00911613 -0.0139294" rpy="0 -0 0" />
            <inertia ixx="1.39551e-08" ixy="5.13005e-14" ixz="-6.45085e-14" iyy="6.46159e-08" iyz="-7.66703e-11" izz="6.44378e-08" />
        </inertial>
        <visual>
            <origin xyz="0 0 0" rpy="0 -0 0" />
            <geometry>
                <mesh filename="package://axol_kit/meshes/_ZEDX_Mini_rev2__Upper_Case_v8.stl" scale="1 1 1" />
            </geometry>
            <material name="0.600000_0.600000_0.600000_0.000000_0.000000">
                <color rgba="0.6 0.6 0.6 1" />
            </material>
        </visual>
    </link>
    <link name="base">
        <inertial>
            <mass value="0.02652" />
            <origin xyz="3.11933e-17 -5.92795e-18 -0.425" rpy="0 -0 0" />
            <inertia ixx="0.00162855" ixy="0" ixz="0" iyy="0.00174612" iyz="0" izz="0.00018122" />
        </inertial>
        <visual>
            <origin xyz="2.78001e-17 -6.95001e-18 0.06" rpy="0 -0 0" />
            <geometry>
                <mesh filename="package://axol_kit/meshes/Base.stl" scale="1 1 1" />
            </geometry>
            <material name="0.647059_0.647059_0.647059_0.000000_0.000000">
                <color rgba="0.647059 0.647059 0.647059 1" />
            </material>
        </visual>
        <collision>
            <origin xyz="2.78001e-17 -6.95001e-18 0.06" rpy="0 -0 0" />
            <geometry>
                <mesh filename="package://axol_kit/meshes/Base.stl" scale="1 1 1" />
            </geometry>
        </collision>
    </link>
    <link name="bh_tx_mx_xx_xx">
        <inertial>
            <mass value="8.09335e-08" />
            <origin xyz="7.80489e-16 -7.51753e-17 -0.00255352" rpy="0 -0 0" />
            <inertia ixx="1e-9" ixy="0" ixz="0" iyy="1e-9" iyz="0" izz="1e-9" />
        </inertial>
        <visual>
            <origin xyz="0 0 0" rpy="0 -0 0" />
            <geometry>
                <mesh filename="package://axol_kit/meshes/BH_TX_Mx_xx_xx.stl" scale="1 1 1" />
            </geometry>
            <material name="0.301961_0.301961_0.301961_0.000000_0.000000">
                <color rgba="0.301961 0.301961 0.301961 1" />
            </material>
        </visual>
    </link>
    <link name="bh_tx_mx_xx_xx_1">
        <inertial>
            <mass value="8.09335e-08" />
            <origin xyz="7.80494e-16 -7.51744e-17 -0.00255352" rpy="0 -0 0" />
            <inertia ixx="1e-9" ixy="0" ixz="0" iyy="1e-9" iyz="0" izz="1e-9" />
        </inertial>
        <visual>
            <origin xyz="0 0 0" rpy="0 -0 0" />
            <geometry>
                <mesh filename="package://axol_kit/meshes/BH_TX_Mx_xx_xx.stl" scale="1 1 1" />
            </geometry>
            <material name="0.301961_0.301961_0.301961_0.000000_0.000000">
                <color rgba="0.301961 0.301961 0.301961 1" />
            </material>
        </visual>
    </link>
    <link name="bh_tx_mx_xx_xx_2">
        <inertial>
            <mass value="8.09335e-08" />
            <origin xyz="7.80494e-16 -7.51744e-17 -0.00255352" rpy="0 -0 0" />
            <inertia ixx="1e-9" ixy="0" ixz="0" iyy="1e-9" iyz="0" izz="1e-9" />
        </inertial>
        <visual>
            <origin xyz="0 0 0" rpy="0 -0 0" />
            <geometry>
                <mesh filename="package://axol_kit/meshes/BH_TX_Mx_xx_xx.stl" scale="1 1 1" />
            </geometry>
            <material name="0.301961_0.301961_0.301961_0.000000_0.000000">
                <color rgba="0.301961 0.301961 0.301961 1" />
            </material>
        </visual>
    </link>
    <link name="bh_tx_mx_xx_xx_3">
        <inertial>
            <mass value="8.09335e-08" />
            <origin xyz="7.80494e-16 -7.51744e-17 -0.00255352" rpy="0 -0 0" />
            <inertia ixx="1e-9" ixy="0" ixz="0" iyy="1e-9" iyz="0" izz="1e-9" />
        </inertial>
        <visual>
            <origin xyz="0 0 0" rpy="0 -0 0" />
            <geometry>
                <mesh filename="package://axol_kit/meshes/BH_TX_Mx_xx_xx.stl" scale="1 1 1" />
            </geometry>
            <material name="0.301961_0.301961_0.301961_0.000000_0.000000">
                <color rgba="0.301961 0.301961 0.301961 1" />
            </material>
        </visual>
    </link>
    <link name="camera_component___body_zed_x_one___front">
        <inertial>
            <mass value="5.01838e-06" />
            <origin xyz="-1.25963e-05 0.00419194 0.000128945" rpy="0 -0 0" />
            <inertia ixx="4.28093e-10" ixy="6.50617e-14" ixz="-6.2144e-13" iyy="6.44756e-10" iyz="1.6266e-12" izz="4.20508e-10" />
        </inertial>
        <visual>
            <origin xyz="0 0 0" rpy="0 -0 0" />
            <geometry>
                <mesh filename="package://axol_kit/meshes/Camera_Component___Body_ZED_X_One___Front.stl" scale="1 1 1" />
            </geometry>
            <material name="0.301961_0.301961_0.301961_0.000000_0.000000">
                <color rgba="0.301961 0.301961 0.301961 1" />
            </material>
        </visual>
    </link>
    <link name="camera_component___body_zed_x_one___front_1">
        <inertial>
            <mass value="5.01838e-06" />
            <origin xyz="-1.25963e-05 0.00419194 0.000128945" rpy="0 -0 0" />
            <inertia ixx="4.28093e-10" ixy="6.50617e-14" ixz="-6.2144e-13" iyy="6.44756e-10" iyz="1.6266e-12" izz="4.20508e-10" />
        </inertial>
        <visual>
            <origin xyz="0 0 0" rpy="0 -0 0" />
            <geometry>
                <mesh filename="package://axol_kit/meshes/Camera_Component___Body_ZED_X_One___Front.stl" scale="1 1 1" />
            </geometry>
            <material name="0.301961_0.301961_0.301961_0.000000_0.000000">
                <color rgba="0.301961 0.301961 0.301961 1" />
            </material>
        </visual>
    </link>
    <link name="camera_component___body_zed_x_one___rear">
        <inertial>
            <mass value="1.9326e-06" />
            <origin xyz="-1.88029e-05 -4.47597e-06 -0.00302087" rpy="0 -0 0" />
            <inertia ixx="1.40109e-10" ixy="7.72126e-13" ixz="-2.97297e-13" iyy="1.43122e-10" iyz="-6.90682e-13" izz="2.65932e-10" />
        </inertial>
        <visual>
            <origin xyz="0 0 0" rpy="0 -0 0" />
            <geometry>
                <mesh filename="package://axol_kit/meshes/Camera_Component___Body_ZED_X_One___Rear.stl" scale="1 1 1" />
            </geometry>
            <material name="0.301961_0.301961_0.301961_0.000000_0.000000">
                <color rgba="0.301961 0.301961 0.301961 1" />
            </material>
        </visual>
    </link>
    <link name="camera_component___body_zed_x_one___rear_1">
        <inertial>
            <mass value="1.9326e-06" />
            <origin xyz="-1.88029e-05 -4.47597e-06 -0.00302087" rpy="0 -0 0" />
            <inertia ixx="1.40109e-10" ixy="7.72126e-13" ixz="-2.97297e-13" iyy="1.43122e-10" iyz="-6.90682e-13" izz="2.65932e-10" />
        </inertial>
        <visual>
            <origin xyz="0 0 0" rpy="0 -0 0" />
            <geometry>
                <mesh filename="package://axol_kit/meshes/Camera_Component___Body_ZED_X_One___Rear.stl" scale="1 1 1" />
            </geometry>
            <material name="0.301961_0.301961_0.301961_0.000000_0.000000">
                <color rgba="0.301961 0.301961 0.301961 1" />
            </material>
        </visual>
    </link>
    <link name="camera_component___connector___fakra_plug">
        <inertial>
            <mass value="7.34727e-07" />
            <origin xyz="0.000113826 0.00123757 1.72143e-07" rpy="0 -0 0" />
            <inertia ixx="1.86844e-11" ixy="-2.52794e-13" ixz="0" iyy="1.48796e-11" iyz="0" izz="1.41152e-11" />
        </inertial>
        <visual>
            <origin xyz="0 0 0" rpy="0 -0 0" />
            <geometry>
                <mesh filename="package://axol_kit/meshes/Camera_Component___Connector___FAKRA_Plug.stl" scale="1 1 1" />
            </geometry>
            <material name="0.917647_0.917647_0.917647_0.000000_0.000000">
                <color rgba="0.917647 0.917647 0.917647 1" />
            </material>
        </visual>
    </link>
    <link name="camera_component___connector___fakra_plug_1">
        <inertial>
            <mass value="7.34727e-07" />
            <origin xyz="0.000113826 0.00123757 1.72143e-07" rpy="0 -0 0" />
            <inertia ixx="1.86844e-11" ixy="-2.52794e-13" ixz="0" iyy="1.48796e-11" iyz="0" izz="1.41152e-11" />
        </inertial>
        <visual>
            <origin xyz="0 0 0" rpy="0 -0 0" />
            <geometry>
                <mesh filename="package://axol_kit/meshes/Camera_Component___Connector___FAKRA_Plug.stl" scale="1 1 1" />
            </geometry>
            <material name="0.917647_0.917647_0.917647_0.000000_0.000000">
                <color rgba="0.917647 0.917647 0.917647 1" />
            </material>
        </visual>
    </link>
    <link name="camera_component___seal___zed_x_one">
        <inertial>
            <mass value="7.84626e-08" />
            <origin xyz="-1.26838e-17 4.53507e-18 -0.0005" rpy="0 -0 0" />
            <inertia ixx="5.86845e-12" ixy="0" ixz="0" iyy="5.86845e-12" iyz="0" izz="1.17238e-11" />
        </inertial>
        <visual>
            <origin xyz="0 0 0" rpy="0 -0 0" />
            <geometry>
                <mesh filename="package://axol_kit/meshes/Camera_Component___Seal___ZED_X_One.stl" scale="1 1 1" />
            </geometry>
            <material name="0.000000_0.000000_0.000000_0.000000_0.000000">
                <color rgba="0 0 0 1" />
            </material>
        </visual>
    </link>
    <link name="camera_component___seal___zed_x_one_1">
        <inertial>
            <mass value="7.84626e-08" />
            <origin xyz="-1.26838e-17 4.53507e-18 -0.0005" rpy="0 -0 0" />
            <inertia ixx="5.86845e-12" ixy="0" ixz="0" iyy="5.86845e-12" iyz="0" izz="1.17238e-11" />
        </inertial>
        <visual>
            <origin xyz="0 0 0" rpy="0 -0 0" />
            <geometry>
                <mesh filename="package://axol_kit/meshes/Camera_Component___Seal___ZED_X_One.stl" scale="1 1 1" />
            </geometry>
            <material name="0.000000_0.000000_0.000000_0.000000_0.000000">
                <color rgba="0 0 0 1" />
            </material>
        </visual>
    </link>
    <link name="fisheye_lens__1_" />
    <link name="fisheye_lens__1__1" />
    <link name="head_mount__1_" />
    <link name="hexalobular_socket_head_cap_screw_iso14579_m2x0_4x10">
        <inertial>
            <mass value="4.53311e-08" />
            <origin xyz="0.00323346 -5.10983e-14 8.79916e-14" rpy="0 -0 0" />
            <inertia ixx="1e-9" ixy="0" ixz="0" iyy="1e-9" iyz="0" izz="1e-9" />
        </inertial>
        <visual>
            <origin xyz="0 0 0" rpy="0 -0 0" />
            <geometry>
                <mesh filename="package://axol_kit/meshes/Hexalobular_socket_head_cap_screw_ISO14579_M2x0_4x10.stl" scale="1 1 1" />
            </geometry>
            <material name="0.301961_0.301961_0.301961_0.000000_0.000000">
                <color rgba="0.301961 0.301961 0.301961 1" />
            </material>
        </visual>
    </link>
    <link name="hexalobular_socket_head_cap_screw_iso14579_m2x0_4x10_1">
        <inertial>
            <mass value="4.53311e-08" />
            <origin xyz="0.00323346 -5.10983e-14 8.79916e-14" rpy="0 -0 0" />
            <inertia ixx="1e-9" ixy="0" ixz="0" iyy="1e-9" iyz="0" izz="1e-9" />
        </inertial>
        <visual>
            <origin xyz="0 0 0" rpy="0 -0 0" />
            <geometry>
                <mesh filename="package://axol_kit/meshes/Hexalobular_socket_head_cap_screw_ISO14579_M2x0_4x10.stl" scale="1 1 1" />
            </geometry>
            <material name="0.301961_0.301961_0.301961_0.000000_0.000000">
                <color rgba="0.301961 0.301961 0.301961 1" />
            </material>
        </visual>
    </link>
    <link name="hexalobular_socket_head_cap_screw_iso14579_m2x0_4x10_2">
        <inertial>
            <mass value="4.53311e-08" />
            <origin xyz="0.00323346 -5.10983e-14 8.79916e-14" rpy="0 -0 0" />
            <inertia ixx="1e-9" ixy="0" ixz="0" iyy="1e-9" iyz="0" izz="1e-9" />
        </inertial>
        <visual>
            <origin xyz="0 0 0" rpy="0 -0 0" />
            <geometry>
                <mesh filename="package://axol_kit/meshes/Hexalobular_socket_head_cap_screw_ISO14579_M2x0_4x10.stl" scale="1 1 1" />
            </geometry>
            <material name="0.301961_0.301961_0.301961_0.000000_0.000000">
                <color rgba="0.301961 0.301961 0.301961 1" />
            </material>
        </visual>
    </link>
    <link name="hexalobular_socket_head_cap_screw_iso14579_m2x0_4x10_3">
        <inertial>
            <mass value="4.53311e-08" />
            <origin xyz="0.00323346 -5.10983e-14 8.79916e-14" rpy="0 -0 0" />
            <inertia ixx="1e-9" ixy="0" ixz="0" iyy="1e-9" iyz="0" izz="1e-9" />
        </inertial>
        <visual>
            <origin xyz="0 0 0" rpy="0 -0 0" />
            <geometry>
                <mesh filename="package://axol_kit/meshes/Hexalobular_socket_head_cap_screw_ISO14579_M2x0_4x10.stl" scale="1 1 1" />
            </geometry>
            <material name="0.301961_0.301961_0.301961_0.000000_0.000000">
                <color rgba="0.301961 0.301961 0.301961 1" />
            </material>
        </visual>
    </link>
    <link name="hexalobular_socket_head_cap_screw_iso14579_m2x0_4x10_4">
        <inertial>
            <mass value="4.53311e-08" />
            <origin xyz="0.00323346 -5.10983e-14 8.79916e-14" rpy="0 -0 0" />
            <inertia ixx="1e-9" ixy="0" ixz="0" iyy="1e-9" iyz="0" izz="1e-9" />
        </inertial>
        <visual>
            <origin xyz="0 0 0" rpy="0 -0 0" />
            <geometry>
                <mesh filename="package://axol_kit/meshes/Hexalobular_socket_head_cap_screw_ISO14579_M2x0_4x10.stl" scale="1 1 1" />
            </geometry>
            <material name="0.301961_0.301961_0.301961_0.000000_0.000000">
                <color rgba="0.301961 0.301961 0.301961 1" />
            </material>
        </visual>
    </link>
    <link name="hexalobular_socket_head_cap_screw_iso14579_m2x0_4x10_5">
        <inertial>
            <mass value="4.53311e-08" />
            <origin xyz="0.00323346 -5.10983e-14 8.79916e-14" rpy="0 -0 0" />
            <inertia ixx="1e-9" ixy="0" ixz="0" iyy="1e-9" iyz="0" izz="1e-9" />
        </inertial>
        <visual>
            <origin xyz="0 0 0" rpy="0 -0 0" />
            <geometry>
                <mesh filename="package://axol_kit/meshes/Hexalobular_socket_head_cap_screw_ISO14579_M2x0_4x10.stl" scale="1 1 1" />
            </geometry>
            <material name="0.301961_0.301961_0.301961_0.000000_0.000000">
                <color rgba="0.301961 0.301961 0.301961 1" />
            </material>
        </visual>
    </link>
    <link name="hexalobular_socket_head_cap_screw_iso14579_m2x0_4x10_6">
        <inertial>
            <mass value="4.53311e-08" />
            <origin xyz="0.00323346 -5.10983e-14 8.79916e-14" rpy="0 -0 0" />
            <inertia ixx="1e-9" ixy="0" ixz="0" iyy="1e-9" iyz="0" izz="1e-9" />
        </inertial>
        <visual>
            <origin xyz="0 0 0" rpy="0 -0 0" />
            <geometry>
                <mesh filename="package://axol_kit/meshes/Hexalobular_socket_head_cap_screw_ISO14579_M2x0_4x10.stl" scale="1 1 1" />
            </geometry>
            <material name="0.301961_0.301961_0.301961_0.000000_0.000000">
                <color rgba="0.301961 0.301961 0.301961 1" />
            </material>
        </visual>
    </link>
    <link name="hexalobular_socket_head_cap_screw_iso14579_m2x0_4x10_7">
        <inertial>
            <mass value="4.53311e-08" />
            <origin xyz="0.00323346 -5.10983e-14 8.79916e-14" rpy="0 -0 0" />
            <inertia ixx="1e-9" ixy="0" ixz="0" iyy="1e-9" iyz="0" izz="1e-9" />
        </inertial>
        <visual>
            <origin xyz="0 0 0" rpy="0 -0 0" />
            <geometry>
                <mesh filename="package://axol_kit/meshes/Hexalobular_socket_head_cap_screw_ISO14579_M2x0_4x10.stl" scale="1 1 1" />
            </geometry>
            <material name="0.301961_0.301961_0.301961_0.000000_0.000000">
                <color rgba="0.301961 0.301961 0.301961 1" />
            </material>
        </visual>
    </link>
    <link name="hexalobular_socket_pan_head_screw_iso_14583_m2x5">
        <inertial>
            <mass value="3.07707e-08" />
            <origin xyz="0.000943454 -1.51098e-15 -4.90186e-15" rpy="0 -0 0" />
            <inertia ixx="1e-9" ixy="0" ixz="0" iyy="1e-9" iyz="0" izz="1e-9" />
        </inertial>
        <visual>
            <origin xyz="0 0 0" rpy="0 -0 0" />
            <geometry>
                <mesh filename="package://axol_kit/meshes/Hexalobular_socket_pan_head_screw_ISO_14583_M2x5.stl" scale="1 1 1" />
            </geometry>
            <material name="0.690196_0.690196_0.690196_0.000000_0.000000">
                <color rgba="0.690196 0.690196 0.690196 1" />
            </material>
        </visual>
    </link>
    <link name="hexalobular_socket_pan_head_screw_iso_14583_m2x5_1">
        <inertial>
            <mass value="3.07707e-08" />
            <origin xyz="0.000943454 -1.51098e-15 -4.90186e-15" rpy="0 -0 0" />
            <inertia ixx="1e-9" ixy="0" ixz="0" iyy="1e-9" iyz="0" izz="1e-9" />
        </inertial>
        <visual>
            <origin xyz="0 0 0" rpy="0 -0 0" />
            <geometry>
                <mesh filename="package://axol_kit/meshes/Hexalobular_socket_pan_head_screw_ISO_14583_M2x5.stl" scale="1 1 1" />
            </geometry>
            <material name="0.690196_0.690196_0.690196_0.000000_0.000000">
                <color rgba="0.690196 0.690196 0.690196 1" />
            </material>
        </visual>
    </link>
    <link name="hexalobular_socket_pan_head_screw_iso_14583_m2x5_2">
        <inertial>
            <mass value="3.07707e-08" />
            <origin xyz="0.000943454 -1.51098e-15 -4.90186e-15" rpy="0 -0 0" />
            <inertia ixx="1e-9" ixy="0" ixz="0" iyy="1e-9" iyz="0" izz="1e-9" />
        </inertial>
        <visual>
            <origin xyz="0 0 0" rpy="0 -0 0" />
            <geometry>
                <mesh filename="package://axol_kit/meshes/Hexalobular_socket_pan_head_screw_ISO_14583_M2x5.stl" scale="1 1 1" />
            </geometry>
            <material name="0.690196_0.690196_0.690196_0.000000_0.000000">
                <color rgba="0.690196 0.690196 0.690196 1" />
            </material>
        </visual>
    </link>
    <link name="hexalobular_socket_pan_head_screw_iso_14583_m2x5_3">
        <inertial>
            <mass value="3.07707e-08" />
            <origin xyz="0.000943454 -1.51098e-15 -4.90186e-15" rpy="0 -0 0" />
            <inertia ixx="1e-9" ixy="0" ixz="0" iyy="1e-9" iyz="0" izz="1e-9" />
        </inertial>
        <visual>
            <origin xyz="0 0 0" rpy="0 -0 0" />
            <geometry>
                <mesh filename="package://axol_kit/meshes/Hexalobular_socket_pan_head_screw_ISO_14583_M2x5.stl" scale="1 1 1" />
            </geometry>
            <material name="0.690196_0.690196_0.690196_0.000000_0.000000">
                <color rgba="0.690196 0.690196 0.690196 1" />
            </material>
        </visual>
    </link>
    <link name="left_e1">
        <inertial>
            <mass value="5.60993" />
            <origin xyz="5.55112e-17 0.00286547 -0.164964" rpy="0 -0 0" />
            <inertia ixx="0.0620647" ixy="0" ixz="0" iyy="0.0623318" iyz="0.000498283" izz="0.00642157" />
        </inertial>
        <visual>
            <origin xyz="-0.19958 2.34488e-17 0.07335" rpy="0 -0 0" />
            <geometry>
                <mesh filename="package://axol_kit/meshes/Left_E1.stl" scale="1 1 1" />
            </geometry>
            <material name="0.917647_0.917647_0.917647_0.000000_0.000000">
                <color rgba="0.917647 0.917647 0.917647 1" />
            </material>
        </visual>
        <collision>
            <origin xyz="-0.19958 2.34488e-17 0.07335" rpy="0 -0 0" />
            <geometry>
                <mesh filename="package://axol_kit/meshes/Left_E1.stl" scale="1 1 1" />
            </geometry>
        </collision>
    </link>
    <link name="left_e2">
        <inertial>
            <mass value="2.15214" />
            <origin xyz="-0.0256064 5.43634e-18 -0.072044" rpy="0 -0 0" />
            <inertia ixx="0.00432485" ixy="0" ixz="-0.0011614" iyy="0.00518166" iyz="0" izz="0.0034736" />
        </inertial>
        <visual>
            <origin xyz="-0.24187 0 0.362735" rpy="0 -0 0" />
            <geometry>
                <mesh filename="package://axol_kit/meshes/Left_E2.stl" scale="1 1 1" />
            </geometry>
            <material name="0.768627_0.886275_0.952941_0.000000_0.000000">
                <color rgba="0.768627 0.886275 0.952941 1" />
            </material>
        </visual>
        <collision>
            <origin xyz="-0.24187 0 0.362735" rpy="0 -0 0" />
            <geometry>
                <mesh filename="package://axol_kit/meshes/Left_E2.stl" scale="1 1 1" />
            </geometry>
        </collision>
    </link>
    <link name="left_s2">
        <inertial>
            <mass value="2.9365" />
            <origin xyz="0.0652231 1.83545e-17 3.47553e-16" rpy="0 -0 0" />
            <inertia ixx="0.0045088" ixy="0" ixz="0" iyy="0.00576061" iyz="0" izz="0.00517216" />
        </inertial>
        <visual>
            <origin xyz="-0.13 1.83545e-17 -4.58863e-18" rpy="0 -0 0" />
            <geometry>
                <mesh filename="package://axol_kit/meshes/Left_S2.stl" scale="1 1 1" />
            </geometry>
            <material name="0.647059_0.647059_0.647059_0.000000_0.000000">
                <color rgba="0.647059 0.647059 0.647059 1" />
            </material>
        </visual>
        <collision>
            <origin xyz="-0.13 1.83545e-17 -4.58863e-18" rpy="0 -0 0" />
            <geometry>
                <mesh filename="package://axol_kit/meshes/Left_S2.stl" scale="1 1 1" />
            </geometry>
        </collision>
    </link>
    <link name="left_s3">
        <inertial>
            <mass value="2.08078" />
            <origin xyz="5.38752e-11 0.0115864 -0.0302711" rpy="0 -0 0" />
            <inertia ixx="0.00454625" ixy="-3.98478e-12" ixz="5.85857e-12" iyy="0.00471857" iyz="0.00125634" izz="0.0029724" />
        </inertial>
        <visual>
            <origin xyz="-0.19958 0.04475 -3.81639e-16" rpy="0 -0 0" />
            <geometry>
                <mesh filename="package://axol_kit/meshes/Left_S3.stl" scale="1 1 1" />
            </geometry>
            <material name="0.231373_0.380392_0.705882_0.000000_0.000000">
                <color rgba="0.231373 0.380392 0.705882 1" />
            </material>
        </visual>
        <collision>
            <origin xyz="-0.19958 0.04475 -3.81639e-16" rpy="0 -0 0" />
            <geometry>
                <mesh filename="package://axol_kit/meshes/Left_S3.stl" scale="1 1 1" />
            </geometry>
        </collision>
    </link>
    <link name="left_w0">
        <inertial>
            <mass value="1.35486" />
            <origin xyz="8.32667e-17 2.10999e-18 -0.0614121" rpy="0 -0 0" />
            <inertia ixx="0.00266168" ixy="0" ixz="0" iyy="0.00232232" iyz="0" izz="0.00106507" />
        </inertial>
        <visual>
            <origin xyz="-0.19958 0 0.487025" rpy="0 -0 0" />
            <geometry>
                <mesh filename="package://axol_kit/meshes/Left_W0.stl" scale="1 1 1" />
            </geometry>
            <material name="0.972549_0.529412_0.003922_0.000000_0.000000">
                <color rgba="0.972549 0.529412 0.00392157 1" />
            </material>
        </visual>
        <collision>
            <origin xyz="-0.19958 0 0.487025" rpy="0 -0 0" />
            <geometry>
                <mesh filename="package://axol_kit/meshes/Left_W0.stl" scale="1 1 1" />
            </geometry>
        </collision>
    </link>
    <link name="left_w1">
        <inertial>
            <mass value="0.892737" />
            <origin xyz="1.38778e-16 0.0285 -0.0285" rpy="0 -0 0" />
            <inertia ixx="0.00103329" ixy="0" ixz="0" iyy="0.00103329" iyz="0" izz="0.000456835" />
        </inertial>
        <visual>
            <origin xyz="-0.19958 0.0285 0.622695" rpy="0 -0 0" />
            <geometry>
                <mesh filename="package://axol_kit/meshes/Left_W1.stl" scale="1 1 1" />
            </geometry>
            <material name="0.498039_0.498039_0.498039_0.000000_0.000000">
                <color rgba="0.498039 0.498039 0.498039 1" />
            </material>
        </visual>
        <collision>
            <origin xyz="-0.19958 0.0285 0.622695" rpy="0 -0 0" />
            <geometry>
                <mesh filename="package://axol_kit/meshes/Left_W1.stl" scale="1 1 1" />
            </geometry>
        </collision>
    </link>
    <link name="left_w2">
        <inertial>
            <mass value="0.116987" />
            <origin xyz="-0.0285 2.15986e-18 -0.0118233" rpy="0 -0 0" />
            <inertia ixx="6.75912e-05" ixy="0" ixz="0" iyy="0.000128136" iyz="0" izz="0.00011923" />
        </inertial>
        <visual>
            <origin xyz="-0.22808 0 0.679695" rpy="0 -0 0" />
            <geometry>
                <mesh filename="package://axol_kit/meshes/Left_W2.stl" scale="1 1 1" />
            </geometry>
            <material name="0.980392_0.713725_0.003922_0.000000_0.000000">
                <color rgba="0.980392 0.713726 0.00392157 1" />
            </material>
        </visual>
        <collision>
            <origin xyz="-0.22808 0 0.679695" rpy="0 -0 0" />
            <geometry>
                <mesh filename="package://axol_kit/meshes/Left_W2.stl" scale="1 1 1" />
            </geometry>
        </collision>
    </link>
    <link name="part_1">
        <inertial>
            <mass value="1.91383e-05" />
            <origin xyz="0.0212132 -0.0269686 -0.0136276" rpy="0 -0 0" />
            <inertia ixx="2.69834e-08" ixy="0" ixz="0" iyy="1.13422e-08" iyz="-1.00759e-08" izz="2.53886e-08" />
        </inertial>
        <visual>
            <origin xyz="0.0212132 0.0321819 -0.0217322" rpy="0 -0 0" />
            <geometry>
                <mesh filename="package://axol_kit/meshes/Part_1.stl" scale="1 1 1" />
            </geometry>
            <material name="0.647059_0.647059_0.647059_0.000000_0.000000">
                <color rgba="0.647059 0.647059 0.647059 1" />
            </material>
        </visual>
    </link>
    <link name="right_e1">
        <inertial>
            <mass value="5.60993" />
            <origin xyz="-5.55112e-17 0.00286547 -0.164964" rpy="0 -0 0" />
            <inertia ixx="0.0620647" ixy="0" ixz="0" iyy="0.0623318" iyz="0.000498283" izz="0.00642157" />
        </inertial>
        <visual>
            <origin xyz="0.19958 2.34488e-17 0.07335" rpy="0 -0 0" />
            <geometry>
                <mesh filename="package://axol_kit/meshes/Right_E1.stl" scale="1 1 1" />
            </geometry>
            <material name="0.917647_0.917647_0.917647_0.000000_0.000000">
                <color rgba="0.917647 0.917647 0.917647 1" />
            </material>
        </visual>
        <collision>
            <origin xyz="0.19958 2.34488e-17 0.07335" rpy="0 -0 0" />
            <geometry>
                <mesh filename="package://axol_kit/meshes/Right_E1.stl" scale="1 1 1" />
            </geometry>
        </collision>
    </link>
    <link name="right_e2">
        <inertial>
            <mass value="2.15214" />
            <origin xyz="0.0256064 5.19027e-18 -0.072044" rpy="0 -0 0" />
            <inertia ixx="0.00432485" ixy="0" ixz="0.0011614" iyy="0.00518166" iyz="0" izz="0.0034736" />
        </inertial>
        <visual>
            <origin xyz="0.24187 0 0.362735" rpy="0 -0 0" />
            <geometry>
                <mesh filename="package://axol_kit/meshes/Right_E2.stl" scale="1 1 1" />
            </geometry>
            <material name="0.768627_0.886275_0.952941_0.000000_0.000000">
                <color rgba="0.768627 0.886275 0.952941 1" />
            </material>
        </visual>
        <collision>
            <origin xyz="0.24187 0 0.362735" rpy="0 -0 0" />
            <geometry>
                <mesh filename="package://axol_kit/meshes/Right_E2.stl" scale="1 1 1" />
            </geometry>
        </collision>
    </link>
    <link name="right_s2">
        <inertial>
            <mass value="2.9365" />
            <origin xyz="-0.0652231 2.14698e-17 3.48478e-16" rpy="0 -0 0" />
            <inertia ixx="0.0045088" ixy="0" ixz="0" iyy="0.00576061" iyz="0" izz="0.00517216" />
        </inertial>
        <visual>
            <origin xyz="0.13 1.83545e-17 -4.58863e-18" rpy="0 -0 0" />
            <geometry>
                <mesh filename="package://axol_kit/meshes/Right_S2.stl" scale="1 1 1" />
            </geometry>
            <material name="0.647059_0.647059_0.647059_0.000000_0.000000">
                <color rgba="0.647059 0.647059 0.647059 1" />
            </material>
        </visual>
        <collision>
            <origin xyz="0.13 1.83545e-17 -4.58863e-18" rpy="0 -0 0" />
            <geometry>
                <mesh filename="package://axol_kit/meshes/Right_S2.stl" scale="1 1 1" />
            </geometry>
        </collision>
    </link>
    <link name="right_s3">
        <inertial>
            <mass value="2.08078" />
            <origin xyz="-8.34369e-11 0.0115864 -0.0302711" rpy="0 -0 0" />
            <inertia ixx="0.00454625" ixy="1.05569e-11" ixz="-6.49717e-12" iyy="0.00471857" iyz="0.00125634" izz="0.0029724" />
        </inertial>
        <visual>
            <origin xyz="0.19958 0.04475 -3.81639e-16" rpy="0 -0 0" />
            <geometry>
                <mesh filename="package://axol_kit/meshes/Right_S3.stl" scale="1 1 1" />
            </geometry>
            <material name="0.231373_0.380392_0.705882_0.000000_0.000000">
                <color rgba="0.231373 0.380392 0.705882 1" />
            </material>
        </visual>
        <collision>
            <origin xyz="0.19958 0.04475 -3.81639e-16" rpy="0 -0 0" />
            <geometry>
                <mesh filename="package://axol_kit/meshes/Right_S3.stl" scale="1 1 1" />
            </geometry>
        </collision>
    </link>
    <link name="right_w0">
        <inertial>
            <mass value="1.35486" />
            <origin xyz="-8.32667e-17 1.05499e-18 -0.0614121" rpy="0 -0 0" />
            <inertia ixx="0.00266168" ixy="0" ixz="0" iyy="0.00232232" iyz="0" izz="0.00106507" />
        </inertial>
        <visual>
            <origin xyz="0.19958 0 0.487025" rpy="0 -0 0" />
            <geometry>
                <mesh filename="package://axol_kit/meshes/Right_W0.stl" scale="1 1 1" />
            </geometry>
            <material name="0.972549_0.529412_0.003922_0.000000_0.000000">
                <color rgba="0.972549 0.529412 0.00392157 1" />
            </material>
        </visual>
        <collision>
            <origin xyz="0.19958 0 0.487025" rpy="0 -0 0" />
            <geometry>
                <mesh filename="package://axol_kit/meshes/Right_W0.stl" scale="1 1 1" />
            </geometry>
        </collision>
    </link>
    <link name="right_w1">
        <inertial>
            <mass value="0.892737" />
            <origin xyz="-1.38778e-16 -0.0285 -0.0285" rpy="0 -0 0" />
            <inertia ixx="0.00103329" ixy="0" ixz="0" iyy="0.00103329" iyz="0" izz="0.000456835" />
        </inertial>
        <visual>
            <origin xyz="0.19958 -0.0285 0.622695" rpy="0 -0 0" />
            <geometry>
                <mesh filename="package://axol_kit/meshes/Right_W1.stl" scale="1 1 1" />
            </geometry>
            <material name="0.498039_0.498039_0.498039_0.000000_0.000000">
                <color rgba="0.498039 0.498039 0.498039 1" />
            </material>
        </visual>
        <collision>
            <origin xyz="0.19958 -0.0285 0.622695" rpy="0 -0 0" />
            <geometry>
                <mesh filename="package://axol_kit/meshes/Right_W1.stl" scale="1 1 1" />
            </geometry>
        </collision>
    </link>
    <link name="right_w2">
        <inertial>
            <mass value="0.116987" />
            <origin xyz="0.0285 1.20012e-18 -0.0118233" rpy="0 -0 0" />
            <inertia ixx="6.75912e-05" ixy="0" ixz="0" iyy="0.000128136" iyz="0" izz="0.00011923" />
        </inertial>
        <visual>
            <origin xyz="0.22808 0 0.679695" rpy="0 -0 0" />
            <geometry>
                <mesh filename="package://axol_kit/meshes/Right_W2.stl" scale="1 1 1" />
            </geometry>
            <material name="0.980392_0.713725_0.003922_0.000000_0.000000">
                <color rgba="0.980392 0.713726 0.00392157 1" />
            </material>
        </visual>
        <collision>
            <origin xyz="0.22808 0 0.679695" rpy="0 -0 0" />
            <geometry>
                <mesh filename="package://axol_kit/meshes/Right_W2.stl" scale="1 1 1" />
            </geometry>
        </collision>
    </link>
    <link name="root" />
    <link name="s1">
        <inertial>
            <mass value="0.00374359" />
            <origin xyz="-0.0212132 0.0137124 -0.0600062" rpy="0 -0 0" />
            <inertia ixx="8.98407e-06" ixy="0" ixz="0" iyy="2.55825e-05" iyz="1.74736e-10" izz="2.55836e-05" />
        </inertial>
        <visual>
            <origin xyz="-0.0212132 0.0137132 -0.06" rpy="0 -0 0" />
            <geometry>
                <mesh filename="package://axol_kit/meshes/S1.stl" scale="1 1 1" />
            </geometry>
            <material name="0.615686_0.811765_0.929412_0.000000_0.000000">
                <color rgba="0.615686 0.811765 0.929412 1" />
            </material>
        </visual>
        <collision>
            <origin xyz="-0.0212132 0.0137132 -0.06" rpy="0 -0 0" />
            <geometry>
                <mesh filename="package://axol_kit/meshes/S1.stl" scale="1 1 1" />
            </geometry>
        </collision>
    </link>
    <link name="sh_hx_mx_xx_xx">
        <inertial>
            <mass value="4.5363e-08" />
            <origin xyz="1.51593e-19 2.19809e-20 -0.00174688" rpy="0 -0 0" />
            <inertia ixx="1e-9" ixy="0" ixz="0" iyy="1e-9" iyz="0" izz="1e-9" />
        </inertial>
        <visual>
            <origin xyz="0 0 0" rpy="0 -0 0" />
            <geometry>
                <mesh filename="package://axol_kit/meshes/SH_HX_Mx_xx_xx.stl" scale="1 1 1" />
            </geometry>
            <material name="0.301961_0.301961_0.301961_0.000000_0.000000">
                <color rgba="0.301961 0.301961 0.301961 1" />
            </material>
        </visual>
    </link>
    <link name="sh_hx_mx_xx_xx_1">
        <inertial>
            <mass value="4.5363e-08" />
            <origin xyz="1.51593e-19 2.25374e-20 -0.00174688" rpy="0 -0 0" />
            <inertia ixx="1e-9" ixy="0" ixz="0" iyy="1e-9" iyz="0" izz="1e-9" />
        </inertial>
        <visual>
            <origin xyz="0 0 0" rpy="0 -0 0" />
            <geometry>
                <mesh filename="package://axol_kit/meshes/SH_HX_Mx_xx_xx.stl" scale="1 1 1" />
            </geometry>
            <material name="0.301961_0.301961_0.301961_0.000000_0.000000">
                <color rgba="0.301961 0.301961 0.301961 1" />
            </material>
        </visual>
    </link>
    <link name="sh_hx_mx_xx_xx_10">
        <inertial>
            <mass value="1.3323e-07" />
            <origin xyz="-1.45504e-14 6.06316e-21 -0.00192917" rpy="0 -0 0" />
            <inertia ixx="1e-9" ixy="0" ixz="0" iyy="1e-9" iyz="0" izz="1e-9" />
        </inertial>
        <visual>
            <origin xyz="0 0 0" rpy="0 -0 0" />
            <geometry>
                <mesh filename="package://axol_kit/meshes/SH_HX_Mx_xx_xx_2.stl" scale="1 1 1" />
            </geometry>
            <material name="0.301961_0.301961_0.301961_0.000000_0.000000">
                <color rgba="0.301961 0.301961 0.301961 1" />
            </material>
        </visual>
    </link>
    <link name="sh_hx_mx_xx_xx_11">
        <inertial>
            <mass value="2.35003e-07" />
            <origin xyz="1.13223e-19 -2.06242e-20 -0.00056286" rpy="0 -0 0" />
            <inertia ixx="3.14345e-12" ixy="0" ixz="0" iyy="3.14345e-12" iyz="0" izz="1.09812e-12" />
        </inertial>
        <visual>
            <origin xyz="0 0 0" rpy="0 -0 0" />
            <geometry>
                <mesh filename="package://axol_kit/meshes/SH_HX_Mx_xx_xx_1.stl" scale="1 1 1" />
            </geometry>
            <material name="0.301961_0.301961_0.301961_0.000000_0.000000">
                <color rgba="0.301961 0.301961 0.301961 1" />
            </material>
        </visual>
    </link>
    <link name="sh_hx_mx_xx_xx_12">
        <inertial>
            <mass value="1.3323e-07" />
            <origin xyz="-1.45504e-14 7.57895e-21 -0.00192917" rpy="0 -0 0" />
            <inertia ixx="1e-9" ixy="0" ixz="0" iyy="1e-9" iyz="0" izz="1e-9" />
        </inertial>
        <visual>
            <origin xyz="0 0 0" rpy="0 -0 0" />
            <geometry>
                <mesh filename="package://axol_kit/meshes/SH_HX_Mx_xx_xx_2.stl" scale="1 1 1" />
            </geometry>
            <material name="0.301961_0.301961_0.301961_0.000000_0.000000">
                <color rgba="0.301961 0.301961 0.301961 1" />
            </material>
        </visual>
    </link>
    <link name="sh_hx_mx_xx_xx_13">
        <inertial>
            <mass value="2.35003e-07" />
            <origin xyz="1.13223e-19 -2.06242e-20 -0.00056286" rpy="0 -0 0" />
            <inertia ixx="3.14345e-12" ixy="0" ixz="0" iyy="3.14345e-12" iyz="0" izz="1.09812e-12" />
        </inertial>
        <visual>
            <origin xyz="0 0 0" rpy="0 -0 0" />
            <geometry>
                <mesh filename="package://axol_kit/meshes/SH_HX_Mx_xx_xx_1.stl" scale="1 1 1" />
            </geometry>
            <material name="0.301961_0.301961_0.301961_0.000000_0.000000">
                <color rgba="0.301961 0.301961 0.301961 1" />
            </material>
        </visual>
    </link>
    <link name="sh_hx_mx_xx_xx_14">
        <inertial>
            <mass value="2.35003e-07" />
            <origin xyz="1.13223e-19 -2.06242e-20 -0.00056286" rpy="0 -0 0" />
            <inertia ixx="3.14345e-12" ixy="0" ixz="0" iyy="3.14345e-12" iyz="0" izz="1.09812e-12" />
        </inertial>
        <visual>
            <origin xyz="0 0 0" rpy="0 -0 0" />
            <geometry>
                <mesh filename="package://axol_kit/meshes/SH_HX_Mx_xx_xx_1.stl" scale="1 1 1" />
            </geometry>
            <material name="0.301961_0.301961_0.301961_0.000000_0.000000">
                <color rgba="0.301961 0.301961 0.301961 1" />
            </material>
        </visual>
    </link>
    <link name="sh_hx_mx_xx_xx_15">
        <inertial>
            <mass value="1.3323e-07" />
            <origin xyz="-1.45504e-14 6.06316e-21 -0.00192917" rpy="0 -0 0" />
            <inertia ixx="1e-9" ixy="0" ixz="0" iyy="1e-9" iyz="0" izz="1e-9" />
        </inertial>
        <visual>
            <origin xyz="0 0 0" rpy="0 -0 0" />
            <geometry>
                <mesh filename="package://axol_kit/meshes/SH_HX_Mx_xx_xx_2.stl" scale="1 1 1" />
            </geometry>
            <material name="0.301961_0.301961_0.301961_0.000000_0.000000">
                <color rgba="0.301961 0.301961 0.301961 1" />
            </material>
        </visual>
    </link>
    <link name="sh_hx_mx_xx_xx_2">
        <inertial>
            <mass value="4.5363e-08" />
            <origin xyz="1.51593e-19 2.19809e-20 -0.00174688" rpy="0 -0 0" />
            <inertia ixx="1e-9" ixy="0" ixz="0" iyy="1e-9" iyz="0" izz="1e-9" />
        </inertial>
        <visual>
            <origin xyz="0 0 0" rpy="0 -0 0" />
            <geometry>
                <mesh filename="package://axol_kit/meshes/SH_HX_Mx_xx_xx.stl" scale="1 1 1" />
            </geometry>
            <material name="0.301961_0.301961_0.301961_0.000000_0.000000">
                <color rgba="0.301961 0.301961 0.301961 1" />
            </material>
        </visual>
    </link>
    <link name="sh_hx_mx_xx_xx_3">
        <inertial>
            <mass value="4.5363e-08" />
            <origin xyz="1.51593e-19 2.19809e-20 -0.00174688" rpy="0 -0 0" />
            <inertia ixx="1e-9" ixy="0" ixz="0" iyy="1e-9" iyz="0" izz="1e-9" />
        </inertial>
        <visual>
            <origin xyz="0 0 0" rpy="0 -0 0" />
            <geometry>
                <mesh filename="package://axol_kit/meshes/SH_HX_Mx_xx_xx.stl" scale="1 1 1" />
            </geometry>
            <material name="0.301961_0.301961_0.301961_0.000000_0.000000">
                <color rgba="0.301961 0.301961 0.301961 1" />
            </material>
        </visual>
    </link>
    <link name="sh_hx_mx_xx_xx_4">
        <inertial>
            <mass value="4.5363e-08" />
            <origin xyz="1.51593e-19 2.19809e-20 -0.00174688" rpy="0 -0 0" />
            <inertia ixx="1e-9" ixy="0" ixz="0" iyy="1e-9" iyz="0" izz="1e-9" />
        </inertial>
        <visual>
            <origin xyz="0 0 0" rpy="0 -0 0" />
            <geometry>
                <mesh filename="package://axol_kit/meshes/SH_HX_Mx_xx_xx.stl" scale="1 1 1" />
            </geometry>
            <material name="0.301961_0.301961_0.301961_0.000000_0.000000">
                <color rgba="0.301961 0.301961 0.301961 1" />
            </material>
        </visual>
    </link>
    <link name="sh_hx_mx_xx_xx_5">
        <inertial>
            <mass value="4.5363e-08" />
            <origin xyz="1.51593e-19 2.19809e-20 -0.00174688" rpy="0 -0 0" />
            <inertia ixx="1e-9" ixy="0" ixz="0" iyy="1e-9" iyz="0" izz="1e-9" />
        </inertial>
        <visual>
            <origin xyz="0 0 0" rpy="0 -0 0" />
            <geometry>
                <mesh filename="package://axol_kit/meshes/SH_HX_Mx_xx_xx.stl" scale="1 1 1" />
            </geometry>
            <material name="0.301961_0.301961_0.301961_0.000000_0.000000">
                <color rgba="0.301961 0.301961 0.301961 1" />
            </material>
        </visual>
    </link>
    <link name="sh_hx_mx_xx_xx_6">
        <inertial>
            <mass value="4.5363e-08" />
            <origin xyz="1.51593e-19 2.19809e-20 -0.00174688" rpy="0 -0 0" />
            <inertia ixx="1e-9" ixy="0" ixz="0" iyy="1e-9" iyz="0" izz="1e-9" />
        </inertial>
        <visual>
            <origin xyz="0 0 0" rpy="0 -0 0" />
            <geometry>
                <mesh filename="package://axol_kit/meshes/SH_HX_Mx_xx_xx.stl" scale="1 1 1" />
            </geometry>
            <material name="0.301961_0.301961_0.301961_0.000000_0.000000">
                <color rgba="0.301961 0.301961 0.301961 1" />
            </material>
        </visual>
    </link>
    <link name="sh_hx_mx_xx_xx_7">
        <inertial>
            <mass value="4.5363e-08" />
            <origin xyz="1.51593e-19 2.19809e-20 -0.00174688" rpy="0 -0 0" />
            <inertia ixx="1e-9" ixy="0" ixz="0" iyy="1e-9" iyz="0" izz="1e-9" />
        </inertial>
        <visual>
            <origin xyz="0 0 0" rpy="0 -0 0" />
            <geometry>
                <mesh filename="package://axol_kit/meshes/SH_HX_Mx_xx_xx.stl" scale="1 1 1" />
            </geometry>
            <material name="0.301961_0.301961_0.301961_0.000000_0.000000">
                <color rgba="0.301961 0.301961 0.301961 1" />
            </material>
        </visual>
    </link>
    <link name="sh_hx_mx_xx_xx_8">
        <inertial>
            <mass value="2.35003e-07" />
            <origin xyz="1.11504e-19 -2.06242e-20 -0.00056286" rpy="0 -0 0" />
            <inertia ixx="3.14345e-12" ixy="0" ixz="0" iyy="3.14345e-12" iyz="0" izz="1.09812e-12" />
        </inertial>
        <visual>
            <origin xyz="0 0 0" rpy="0 -0 0" />
            <geometry>
                <mesh filename="package://axol_kit/meshes/SH_HX_Mx_xx_xx_1.stl" scale="1 1 1" />
            </geometry>
            <material name="0.301961_0.301961_0.301961_0.000000_0.000000">
                <color rgba="0.301961 0.301961 0.301961 1" />
            </material>
        </visual>
    </link>
    <link name="sh_hx_mx_xx_xx_9">
        <inertial>
            <mass value="1.3323e-07" />
            <origin xyz="-1.45504e-14 6.06316e-21 -0.00192917" rpy="0 -0 0" />
            <inertia ixx="1e-9" ixy="0" ixz="0" iyy="1e-9" iyz="0" izz="1e-9" />
        </inertial>
        <visual>
            <origin xyz="0 0 0" rpy="0 -0 0" />
            <geometry>
                <mesh filename="package://axol_kit/meshes/SH_HX_Mx_xx_xx_2.stl" scale="1 1 1" />
            </geometry>
            <material name="0.301961_0.301961_0.301961_0.000000_0.000000">
                <color rgba="0.301961 0.301961 0.301961 1" />
            </material>
        </visual>
    </link>
    <link name="wrist_mount">
        <inertial>
            <mass value="0.0485648" />
            <origin xyz="0.02 -0.000392963 0.0242789" rpy="0 -0 0" />
            <inertia ixx="1.79324e-05" ixy="0" ixz="0" iyy="2.28976e-05" iyz="3.01853e-06" izz="6.62217e-06" />
        </inertial>
        <visual>
            <origin xyz="0.02 0.003175 -0.0285001" rpy="0 -0 0" />
            <geometry>
                <mesh filename="package://axol_kit/meshes/Wrist_Mount.stl" scale="1 1 1" />
            </geometry>
            <material name="0.647059_0.647059_0.647059_0.000000_0.000000">
                <color rgba="0.647059 0.647059 0.647059 1" />
            </material>
        </visual>
    </link>
    <link name="wrist_mount_1">
        <inertial>
            <mass value="0.0485648" />
            <origin xyz="0.02 -0.000392963 0.0242789" rpy="0 -0 0" />
            <inertia ixx="1.79324e-05" ixy="0" ixz="0" iyy="2.28976e-05" iyz="3.01853e-06" izz="6.62217e-06" />
        </inertial>
        <visual>
            <origin xyz="0.02 0.003175 -0.0285001" rpy="0 -0 0" />
            <geometry>
                <mesh filename="package://axol_kit/meshes/Wrist_Mount.stl" scale="1 1 1" />
            </geometry>
            <material name="0.647059_0.647059_0.647059_0.000000_0.000000">
                <color rgba="0.647059 0.647059 0.647059 1" />
            </material>
        </visual>
    </link>
    <link name="wrist_mount__1_" />
    <link name="wrist_mount__2_" />
    <link name="zed_xg120_asm_smb_jack_to_fakra_plug_adapter_v1">
        <inertial>
            <mass value="1.14537e-11" />
            <origin xyz="-9.02742e-19 -4.28005e-20 -0.000383286" rpy="0 -0 0" />
            <inertia ixx="1e-9" ixy="0" ixz="0" iyy="1e-9" iyz="0" izz="1e-9" />
        </inertial>
        <visual>
            <origin xyz="0 0 0" rpy="0 -0 0" />
            <geometry>
                <mesh filename="package://axol_kit/meshes/ZED_XG120_ASM_SMB_JACK_TO_FAKRA_PLUG_ADAPTER_v1.stl" scale="1 1 1" />
            </geometry>
            <material name="1.000000_1.000000_1.000000_0.000000_0.000000">
                <color rgba="1 1 1 1" />
            </material>
        </visual>
    </link>
    <link name="zed_xg120_asm_smb_jack_to_fakra_plug_adapter_v1_1">
        <inertial>
            <mass value="3.11997e-10" />
            <origin xyz="7.75895e-15 2.35517e-16 0.000120951" rpy="0 -0 0" />
            <inertia ixx="1e-9" ixy="0" ixz="0" iyy="1e-9" iyz="0" izz="1e-9" />
        </inertial>
        <visual>
            <origin xyz="0 0 0" rpy="0 -0 0" />
            <geometry>
                <mesh filename="package://axol_kit/meshes/ZED_XG120_ASM_SMB_JACK_TO_FAKRA_PLUG_ADAPTER_v1_1.stl" scale="1 1 1" />
            </geometry>
            <material name="1.000000_1.000000_1.000000_0.000000_0.000000">
                <color rgba="1 1 1 1" />
            </material>
        </visual>
    </link>
    <link name="zed_xg120_asm_smb_jack_to_fakra_plug_adapter_v1_2">
        <inertial>
            <mass value="5.4086e-09" />
            <origin xyz="-0.000134896 -4.94237e-14 -0.00445" rpy="0 -0 0" />
            <inertia ixx="1e-9" ixy="0" ixz="0" iyy="1e-9" iyz="0" izz="1e-9" />
        </inertial>
        <visual>
            <origin xyz="0 0 0" rpy="0 -0 0" />
            <geometry>
                <mesh filename="package://axol_kit/meshes/ZED_XG120_ASM_SMB_JACK_TO_FAKRA_PLUG_ADAPTER_v1_2.stl" scale="1 1 1" />
            </geometry>
            <material name="1.000000_1.000000_1.000000_0.000000_0.000000">
                <color rgba="1 1 1 1" />
            </material>
        </visual>
    </link>
    <link name="zed_xg120_asm_smb_jack_to_fakra_plug_adapter_v1_3">
        <inertial>
            <mass value="7.34727e-07" />
            <origin xyz="0.000113826 -1.72087e-07 0.00123757" rpy="0 -0 0" />
            <inertia ixx="1.86844e-11" ixy="0" ixz="-2.52793e-13" iyy="1.41152e-11" iyz="0" izz="1.48796e-11" />
        </inertial>
        <visual>
            <origin xyz="0 0 0" rpy="0 -0 0" />
            <geometry>
                <mesh filename="package://axol_kit/meshes/ZED_XG120_ASM_SMB_JACK_TO_FAKRA_PLUG_ADAPTER_v1_3.stl" scale="1 1 1" />
            </geometry>
            <material name="1.000000_1.000000_1.000000_0.000000_0.000000">
                <color rgba="1 1 1 1" />
            </material>
        </visual>
    </link>
    <link name="zed_xg120_asm_smb_jack_to_fakra_plug_adapter_v1_4">
        <inertial>
            <mass value="2.1971e-09" />
            <origin xyz="9.09381e-15 -1.50937e-16 0.00451812" rpy="0 -0 0" />
            <inertia ixx="1e-9" ixy="0" ixz="0" iyy="1e-9" iyz="0" izz="1e-9" />
        </inertial>
        <visual>
            <origin xyz="0 0 0" rpy="0 -0 0" />
            <geometry>
                <mesh filename="package://axol_kit/meshes/ZED_XG120_ASM_SMB_JACK_TO_FAKRA_PLUG_ADAPTER_v1_4.stl" scale="1 1 1" />
            </geometry>
            <material name="1.000000_1.000000_1.000000_0.000000_0.000000">
                <color rgba="1 1 1 1" />
            </material>
        </visual>
    </link>
    <joint name="base" type="fixed">
        <origin xyz="-0.0212132 0.0137132 -0.12" rpy="0 1.06752e-16 0" />
        <axis xyz="1.06752e-16 0 1" />
        <parent link="s1" />
        <child link="base" />
    </joint>
    <joint name="fastened_1" type="fixed">
        <origin xyz="0.02 -0.00802438 0.0582209" rpy="2.70526 -2.38974e-16 -3.14159" />
        <axis xyz="-0 -1 -0" />
        <parent link="wrist_mount_1" />
        <child link="camera_component___body_zed_x_one___front_1" />
    </joint>
    <joint name="fastened_1_1" type="fixed">
        <origin xyz="0.0397132 -0.0715941 -0.0307218" rpy="-0.349066 4.20261e-16 -3.14159" />
        <axis xyz="0 0 1" />
        <parent link="part_1" />
        <child link="_zedx_mini_rev2__lower_case_v13" />
    </joint>
    <joint name="fastened_1_2" type="fixed">
        <origin xyz="0.0424264 0.00243219 -0.00204085" rpy="0.872665 8.85932e-18 2.45965e-16" />
        <axis xyz="-1.06752e-16 -0 1" />
        <parent link="part_1" />
        <child link="s1" />
    </joint>
    <joint name="fastened_1_3" type="fixed">
        <origin xyz="0.02 -0.00802438 0.0582209" rpy="2.70526 -2.38974e-16 -3.14159" />
        <axis xyz="-0 -1 -0" />
        <parent link="wrist_mount" />
        <child link="camera_component___body_zed_x_one___front" />
    </joint>
    <joint name="fastened_2" type="fixed">
        <origin xyz="0.02 -2.77556e-17 -0.0285001" rpy="-1.2326e-32 1.2178e-41 -7.50526e-74" />
        <axis xyz="-0 1 -0" />
        <parent link="wrist_mount_1" />
        <child link="wrist_mount__1_" />
    </joint>
    <joint name="fastened_2_1" type="fixed">
        <origin xyz="0.02 1.38778e-16 -0.0285001" rpy="5.68515e-14 4.29527e-30 6.31089e-30" />
        <axis xyz="-0 1 -0" />
        <parent link="wrist_mount" />
        <child link="wrist_mount__2_" />
    </joint>
    <joint name="fastened_2_2" type="fixed">
        <origin xyz="-0.02 -0.045 0.0285" rpy="-2.02816e-15 -2.61077e-29 -9.48894e-15" />
        <axis xyz="0 -1 0" />
        <parent link="left_gripper_body" />
        <child link="wrist_mount" />
    </joint>
    <joint name="fastened_3" type="fixed">
        <origin xyz="0.0095 -0.00646442 0.0473628" rpy="2.00713 2.36935e-30 -9.9436e-30" />
        <axis xyz="-0 -0 -1" />
        <parent link="wrist_mount_1" />
        <child link="sh_hx_mx_xx_xx_7" />
    </joint>
    <joint name="fastened_3_1" type="fixed">
        <origin xyz="0.0305 -0.00646442 0.0473628" rpy="2.00713 2.36935e-30 -9.9436e-30" />
        <axis xyz="-0 -0 -1" />
        <parent link="wrist_mount_1" />
        <child link="sh_hx_mx_xx_xx_6" />
    </joint>
    <joint name="fastened_3_10" type="fixed">
        <origin xyz="0.0305 -0.00646442 0.0473628" rpy="2.00713 8.78043e-30 -5.34531e-30" />
        <axis xyz="-0 -0 -1" />
        <parent link="wrist_mount" />
        <child link="sh_hx_mx_xx_xx_1" />
    </joint>
    <joint name="fastened_3_11" type="fixed">
        <origin xyz="0.0095 -0.0153394 0.0663953" rpy="2.00713 8.78043e-30 -5.34531e-30" />
        <axis xyz="-0 -0 -1" />
        <parent link="wrist_mount" />
        <child link="sh_hx_mx_xx_xx_3" />
    </joint>
    <joint name="fastened_3_12" type="fixed">
        <origin xyz="0.0305 -0.0153394 0.0663953" rpy="2.00713 8.78043e-30 -5.34531e-30" />
        <axis xyz="-0 -0 -1" />
        <parent link="wrist_mount" />
        <child link="sh_hx_mx_xx_xx_2" />
    </joint>
    <joint name="fastened_3_2" type="fixed">
        <origin xyz="0.0095 -0.0153394 0.0663953" rpy="2.00713 2.36935e-30 -9.9436e-30" />
        <axis xyz="-0 -0 -1" />
        <parent link="wrist_mount_1" />
        <child link="sh_hx_mx_xx_xx_5" />
    </joint>
    <joint name="fastened_3_3" type="fixed">
        <origin xyz="0.0305 -0.0153394 0.0663953" rpy="2.00713 2.36935e-30 -9.9436e-30" />
        <axis xyz="-0 -0 -1" />
        <parent link="wrist_mount_1" />
        <child link="sh_hx_mx_xx_xx_4" />
    </joint>
    <joint name="fastened_3_4" type="fixed">
        <origin xyz="-0.02 -0.045 0.0285" rpy="-2.02816e-15 -1.74249e-29 -9.48894e-15" />
        <axis xyz="0 -1 0" />
        <parent link="right_gripper_body" />
        <child link="wrist_mount_1" />
    </joint>
    <joint name="fastened_3_5" type="fixed">
        <origin xyz="0.0397132 -0.0867754 -0.0328686" rpy="-0.349066 1.62899e-16 -3.14159" />
        <axis xyz="-0 -0 -1" />
        <parent link="part_1" />
        <child link="sh_hx_mx_xx_xx_14" />
    </joint>
    <joint name="fastened_3_6" type="fixed">
        <origin xyz="0.0027132 -0.0726801 -0.0277383" rpy="-0.349066 1.62899e-16 -3.14159" />
        <axis xyz="-0 -0 -1" />
        <parent link="part_1" />
        <child link="sh_hx_mx_xx_xx_8" />
    </joint>
    <joint name="fastened_3_7" type="fixed">
        <origin xyz="0.0397132 -0.0726801 -0.0277383" rpy="-0.349066 1.62899e-16 -3.14159" />
        <axis xyz="-0 -0 -1" />
        <parent link="part_1" />
        <child link="sh_hx_mx_xx_xx_13" />
    </joint>
    <joint name="fastened_3_8" type="fixed">
        <origin xyz="0.0027132 -0.0867754 -0.0328686" rpy="-0.349066 1.62899e-16 -3.14159" />
        <axis xyz="-0 -0 -1" />
        <parent link="part_1" />
        <child link="sh_hx_mx_xx_xx_11" />
    </joint>
    <joint name="fastened_3_9" type="fixed">
        <origin xyz="0.0095 -0.00646442 0.0473628" rpy="2.00713 8.78043e-30 -5.34531e-30" />
        <axis xyz="-0 -0 -1" />
        <parent link="wrist_mount" />
        <child link="sh_hx_mx_xx_xx" />
    </joint>
    <joint name="fastened_4" type="fixed">
        <origin xyz="-1.11022e-16 0.003175 -6.93889e-18" rpy="-1.5708 9.46633e-30 7.64394e-30" />
        <axis xyz="-0 -0 -1" />
        <parent link="wrist_mount_1" />
        <child link="bh_tx_mx_xx_xx_3" />
    </joint>
    <joint name="fastened_4_1" type="fixed">
        <origin xyz="0.04 0.003175 -1.04083e-17" rpy="-1.5708 9.46633e-30 7.64394e-30" />
        <axis xyz="-0 -0 -1" />
        <parent link="wrist_mount_1" />
        <child link="bh_tx_mx_xx_xx_2" />
    </joint>
    <joint name="fastened_4_2" type="fixed">
        <origin xyz="0.0424264 -2.22045e-15 -6.66134e-16" rpy="0.872665 -1.84577e-16 3.2691e-16" />
        <axis xyz="-0 -0 -1" />
        <parent link="part_1" />
        <child link="sh_hx_mx_xx_xx_9" />
    </joint>
    <joint name="fastened_4_3" type="fixed">
        <origin xyz="0.0424264 0.0272712 0.0325005" rpy="0.872665 -1.84577e-16 3.2691e-16" />
        <axis xyz="-0 -0 -1" />
        <parent link="part_1" />
        <child link="sh_hx_mx_xx_xx_15" />
    </joint>
    <joint name="fastened_4_4" type="fixed">
        <origin xyz="-2.15106e-16 0.0272712 0.0325005" rpy="0.872665 -1.84577e-16 3.2691e-16" />
        <axis xyz="-0 -0 -1" />
        <parent link="part_1" />
        <child link="sh_hx_mx_xx_xx_12" />
    </joint>
    <joint name="fastened_4_5" type="fixed">
        <origin xyz="2.08167e-16 1.87871e-15 -1.22125e-15" rpy="-0.872665 -2.98603e-17 -1.74992e-16" />
        <axis xyz="0 -0.766044 0.642788" />
        <parent link="sh_hx_mx_xx_xx_10" />
        <child link="part_1" />
    </joint>
    <joint name="fastened_4_6" type="fixed">
        <origin xyz="0 0.003175 -1.60982e-15" rpy="-1.5708 4.29527e-30 1.35364e-29" />
        <axis xyz="-0 -0 -1" />
        <parent link="wrist_mount" />
        <child link="bh_tx_mx_xx_xx" />
    </joint>
    <joint name="fastened_4_7" type="fixed">
        <origin xyz="0.04 0.003175 -1.61676e-15" rpy="-1.5708 4.29527e-30 1.35364e-29" />
        <axis xyz="-0 -0 -1" />
        <parent link="wrist_mount" />
        <child link="bh_tx_mx_xx_xx_1" />
    </joint>
    <joint name="fastened_5" type="fixed">
        <origin xyz="0.0212132 0.0160678 0.0142094" rpy="0.872665 -8.96395e-17 2.46283e-16" />
        <axis xyz="0 0 1" />
        <parent link="part_1" />
        <child link="head_mount__1_" />
    </joint>
    <joint name="group_1_fastened_joint" type="fixed">
        <origin xyz="0 2.77556e-17 0.0136" rpy="0 -0 5.55112e-17" />
        <axis xyz="0 0 1" />
        <parent link="hexalobular_socket_pan_head_screw_iso_14583_m2x5_3" />
        <child link="hexalobular_socket_pan_head_screw_iso_14583_m2x5_2" />
    </joint>
    <joint name="group_1_fastened_joint_1" type="fixed">
        <origin xyz="2.77556e-17 2.77556e-17 -0.021" rpy="-1.57772e-30 1.2446e-60 1.57772e-30" />
        <axis xyz="0 0 1" />
        <parent link="hexalobular_socket_head_cap_screw_iso14579_m2x0_4x10_5" />
        <child link="hexalobular_socket_head_cap_screw_iso14579_m2x0_4x10_7" />
    </joint>
    <joint name="group_1_fastened_joint_10" type="fixed">
        <origin xyz="0 -5.91646e-31 0" rpy="-1.97215e-31 -5.55112e-17 1.47911e-31" />
        <axis xyz="0 0 1" />
        <parent link="zed_xg120_asm_smb_jack_to_fakra_plug_adapter_v1_4" />
        <child link="zed_xg120_asm_smb_jack_to_fakra_plug_adapter_v1_1" />
    </joint>
    <joint name="group_1_fastened_joint_11" type="fixed">
        <origin xyz="0.00589979 -0.00173896 -0.00564672" rpy="1.21543e-63 -4.93038e-32 -4.93038e-32" />
        <axis xyz="-0 -0 -1" />
        <parent link="_zedx_mini_rev2__lower_case_v13" />
        <child link="_zedx_mini_rev2__upper_case_v8" />
    </joint>
    <joint name="group_1_fastened_joint_12" type="fixed">
        <origin xyz="1.73472e-18 0 0" rpy="1.21543e-63 -4.93038e-32 -4.93038e-32" />
        <axis xyz="-0 -0 -1" />
        <parent link="_zedx_mini_rev2__plastron_v2_2" />
        <child link="_zedx_mini_rev2__plastron_v2_1" />
    </joint>
    <joint name="group_1_fastened_joint_13" type="fixed">
        <origin xyz="0.0068 -6.66134e-16 0.00227" rpy="3.14159 -2.37701e-17 -1.5708" />
        <axis xyz="0 0 1" />
        <parent link="_zed_x_502__zed_x_50_lch_asm_din_en_iso7045_m2x5_4_8h_v1" />
        <child link="zed_xg120_asm_smb_jack_to_fakra_plug_adapter_v1_4" />
    </joint>
    <joint name="group_1_fastened_joint_14" type="fixed">
        <origin xyz="-0.0136 -1.11022e-16 0" rpy="8.50803e-63 9.86076e-32 1.72563e-31" />
        <axis xyz="0 0 1" />
        <parent link="_zed_x_502__zed_x_50_lch_asm_din_en_iso7045_m2x5_4_8h_v1_1" />
        <child link="_zed_x_502__zed_x_50_lch_asm_din_en_iso7045_m2x5_4_8h_v1" />
    </joint>
    <joint name="group_1_fastened_joint_15" type="fixed">
        <origin xyz="0.0185 0.00337099 -0.00067" rpy="-5.26365e-15 2.37701e-17 1.5708" />
        <axis xyz="0 0 1" />
        <parent link="_zedx_mini_rev2__lower_case_v13" />
        <child link="zed_xg120_asm_smb_jack_to_fakra_plug_adapter_v1_2" />
    </joint>
    <joint name="group_1_fastened_joint_16" type="fixed">
        <origin xyz="1.1389e-05 0 -6.66134e-16" rpy="1.21543e-63 -4.93038e-32 -4.93038e-32" />
        <axis xyz="-0 -0 -1" />
        <parent link="_zedx_mini_rev2__upper_case_v8" />
        <child link="_zedx_mini_rev2__plastron_v2_2" />
    </joint>
    <joint name="group_1_fastened_joint_17" type="fixed">
        <origin xyz="0 -5.91646e-31 0" rpy="-1.97215e-31 -5.55112e-17 1.47911e-31" />
        <axis xyz="0 0 1" />
        <parent link="zed_xg120_asm_smb_jack_to_fakra_plug_adapter_v1_2" />
        <child link="zed_xg120_asm_smb_jack_to_fakra_plug_adapter_v1" />
    </joint>
    <joint name="group_1_fastened_joint_18" type="fixed">
        <origin xyz="0.000250214 0.000307387 0.000641526" rpy="-1.97215e-31 -5.55112e-17 1.47911e-31" />
        <axis xyz="0 0 1" />
        <parent link="zed_xg120_asm_smb_jack_to_fakra_plug_adapter_v1_1" />
        <child link="zed_xg120_asm_smb_jack_to_fakra_plug_adapter_v1_3" />
    </joint>
    <joint name="group_1_fastened_joint_19" type="fixed">
        <origin xyz="1.73472e-18 0 0" rpy="1.21543e-63 -4.93038e-32 -4.93038e-32" />
        <axis xyz="-0 -0 -1" />
        <parent link="_zedx_mini_rev2__plastron_v2_1" />
        <child link="_zedx_mini_rev2__plastron_v2" />
    </joint>
    <joint name="group_1_fastened_joint_2" type="fixed">
        <origin xyz="2.77556e-17 0.021 0.021" rpy="-1.57772e-30 1.2446e-60 1.57772e-30" />
        <axis xyz="0 0 1" />
        <parent link="hexalobular_socket_head_cap_screw_iso14579_m2x0_4x10_4" />
        <child link="hexalobular_socket_head_cap_screw_iso14579_m2x0_4x10_5" />
    </joint>
    <joint name="group_1_fastened_joint_20" type="fixed">
        <origin xyz="-5.55112e-16 -0.0068 0.00227" rpy="-3.14159 5.20814e-15 -1.5708" />
        <axis xyz="0 0 1" />
        <parent link="zed_xg120_asm_smb_jack_to_fakra_plug_adapter_v1" />
        <child link="_zed_x_502__zed_x_50_lch_asm_din_en_iso7045_m2x5_4_8h_v1_1" />
    </joint>
    <joint name="group_1_fastened_joint_21" type="fixed">
        <origin xyz="0 8.32667e-17 0.0136" rpy="1.38778e-17 -1.38778e-17 2.77556e-17" />
        <axis xyz="0 0 1" />
        <parent link="hexalobular_socket_pan_head_screw_iso_14583_m2x5_1" />
        <child link="hexalobular_socket_pan_head_screw_iso_14583_m2x5" />
    </joint>
    <joint name="group_1_fastened_joint_22" type="fixed">
        <origin xyz="0 1.38778e-16 -0.021" rpy="-1.57772e-30 0 0" />
        <axis xyz="0 0 1" />
        <parent link="hexalobular_socket_head_cap_screw_iso14579_m2x0_4x10_3" />
        <child link="hexalobular_socket_head_cap_screw_iso14579_m2x0_4x10_1" />
    </joint>
    <joint name="group_1_fastened_joint_23" type="fixed">
        <origin xyz="-2.77556e-17 0.021 0.021" rpy="-1.57772e-30 0 0" />
        <axis xyz="0 0 1" />
        <parent link="hexalobular_socket_head_cap_screw_iso14579_m2x0_4x10_2" />
        <child link="hexalobular_socket_head_cap_screw_iso14579_m2x0_4x10_3" />
    </joint>
    <joint name="group_1_fastened_joint_24" type="fixed">
        <origin xyz="-0.00497 -0.0137181 0.00124526" rpy="-1.08088 1.74863e-16 8.32299e-18" />
        <axis xyz="0 0 1" />
        <parent link="hexalobular_socket_head_cap_screw_iso14579_m2x0_4x10_1" />
        <child link="hexalobular_socket_pan_head_screw_iso_14583_m2x5_1" />
    </joint>
    <joint name="group_1_fastened_joint_25" type="fixed">
        <origin xyz="1.66533e-16 -3.57353e-16 -0.0121" rpy="-9.33452e-60 -4.73317e-30 3.9443e-30" />
        <axis xyz="-0 -0 -1" />
        <parent link="fisheye_lens__1_" />
        <child link="camera_component___seal___zed_x_one" />
    </joint>
    <joint name="group_1_fastened_joint_26" type="fixed">
        <origin xyz="-0.002782 -0.006055 0.00193" rpy="1.5708 -7.77156e-16 1.08088" />
        <axis xyz="0 0 1" />
        <parent link="camera_component___body_zed_x_one___rear" />
        <child link="camera_component___connector___fakra_plug" />
    </joint>
    <joint name="group_1_fastened_joint_27" type="fixed">
        <origin xyz="-2.77556e-17 1.11022e-16 -0.021" rpy="-1.57772e-30 0 0" />
        <axis xyz="0 0 1" />
        <parent link="hexalobular_socket_head_cap_screw_iso14579_m2x0_4x10" />
        <child link="hexalobular_socket_head_cap_screw_iso14579_m2x0_4x10_2" />
    </joint>
    <joint name="group_1_fastened_joint_28" type="fixed">
        <origin xyz="5.55112e-17 0.02022 -5.55112e-17" rpy="-1.5708 3.94353e-30 1.21431e-17" />
        <axis xyz="0 0 1" />
        <parent link="camera_component___body_zed_x_one___front" />
        <child link="camera_component___body_zed_x_one___rear" />
    </joint>
    <joint name="group_1_fastened_joint_29" type="fixed">
        <origin xyz="0.0208575 -0.0043 0.00392973" rpy="-2.06071 5.55112e-17 -1.5708" />
        <axis xyz="0 0 1" />
        <parent link="camera_component___connector___fakra_plug" />
        <child link="hexalobular_socket_head_cap_screw_iso14579_m2x0_4x10" />
    </joint>
    <joint name="group_1_fastened_joint_3" type="fixed">
        <origin xyz="-0.00497 -0.0137181 0.00124526" rpy="-1.08088 1.44331e-16 -1.11055e-17" />
        <axis xyz="0 0 1" />
        <parent link="hexalobular_socket_head_cap_screw_iso14579_m2x0_4x10_7" />
        <child link="hexalobular_socket_pan_head_screw_iso_14583_m2x5_3" />
    </joint>
    <joint name="group_1_fastened_joint_30" type="fixed">
        <origin xyz="-5.55112e-17 0 -6.93889e-18" rpy="-1.5708 2.63678e-16 3.14159" />
        <axis xyz="-0 -0 -1" />
        <parent link="camera_component___body_zed_x_one___front" />
        <child link="fisheye_lens__1_" />
    </joint>
    <joint name="group_1_fastened_joint_4" type="fixed">
        <origin xyz="1.11022e-16 -3.22659e-16 -0.0121" rpy="6.22302e-61 1.57772e-30 7.88861e-31" />
        <axis xyz="-0 -0 -1" />
        <parent link="fisheye_lens__1__1" />
        <child link="camera_component___seal___zed_x_one_1" />
    </joint>
    <joint name="group_1_fastened_joint_5" type="fixed">
        <origin xyz="-0.002782 -0.006055 0.00193" rpy="1.5708 -7.77156e-16 1.08088" />
        <axis xyz="0 0 1" />
        <parent link="camera_component___body_zed_x_one___rear_1" />
        <child link="camera_component___connector___fakra_plug_1" />
    </joint>
    <joint name="group_1_fastened_joint_6" type="fixed">
        <origin xyz="2.77556e-17 5.55112e-17 -0.021" rpy="-1.57772e-30 1.2446e-60 1.57772e-30" />
        <axis xyz="0 0 1" />
        <parent link="hexalobular_socket_head_cap_screw_iso14579_m2x0_4x10_6" />
        <child link="hexalobular_socket_head_cap_screw_iso14579_m2x0_4x10_4" />
    </joint>
    <joint name="group_1_fastened_joint_7" type="fixed">
        <origin xyz="8.32667e-17 0.02022 -1.11022e-16" rpy="-1.5708 9.46556e-30 1.21431e-17" />
        <axis xyz="0 0 1" />
        <parent link="camera_component___body_zed_x_one___front_1" />
        <child link="camera_component___body_zed_x_one___rear_1" />
    </joint>
    <joint name="group_1_fastened_joint_8" type="fixed">
        <origin xyz="0.0208575 -0.0043 0.00392973" rpy="-2.06071 5.55112e-17 -1.5708" />
        <axis xyz="0 0 1" />
        <parent link="camera_component___connector___fakra_plug_1" />
        <child link="hexalobular_socket_head_cap_screw_iso14579_m2x0_4x10_6" />
    </joint>
    <joint name="group_1_fastened_joint_9" type="fixed">
        <origin xyz="2.77556e-17 -2.77556e-17 6.93889e-18" rpy="-1.5708 2.63678e-16 3.14159" />
        <axis xyz="-0 -0 -1" />
        <parent link="camera_component___body_zed_x_one___front_1" />
        <child link="fisheye_lens__1__1" />
    </joint>
    <joint name="hanging_node_to_root_joint" type="fixed">
        <origin xyz="-0.0212132 -0.0137132 0.973175" rpy="2.69507e-14 -2.20045e-16 1.11943e-16" />
        <axis xyz="0 0 1" />
        <parent link="root" />
        <child link="sh_hx_mx_xx_xx_10" />
    </joint>
    <joint name="left_e1_0" type="revolute">
        <origin xyz="0.04229 3.83668e-17 -0.289385" rpy="6.27582e-14 1.30104e-17 5.77135e-18" />
        <axis xyz="-1 0 2.98117e-16" />
        <parent link="left_e1" />
        <child link="left_e2" />
        <limit effort="87.0" velocity="30.0" lower="0.0" upper="2.618" />
    </joint>
    <joint name="left_e2_0" type="revolute">
        <origin xyz="-0.04229 -7.12753e-18 -0.12429" rpy="-3.2474e-15 -6.33174e-17 -2.54576e-14" />
        <axis xyz="0 0 1" />
        <parent link="left_e2" />
        <child link="left_w0" />
        <limit effort="87.0" velocity="30.0" lower="-2.3562" upper="2.3562" />
    </joint>
    <joint name="left_s1_0" type="revolute">
        <origin xyz="0.108787 0.0137132 -0.06" rpy="6.43813e-31 -9.66752e-16 8.11935e-28" />
        <axis xyz="-1 0 0" />
        <parent link="s1" />
        <child link="left_s2" />
        <limit effort="87.0" velocity="30.0" lower="-1.5708" upper="3.1416" />
    </joint>
    <joint name="left_s2_0" type="revolute">
        <origin xyz="0.06958 -0.04475 3.33067e-16" rpy="-8.54059e-31 1.28437e-14 -1.22465e-16" />
        <axis xyz="0 1 0" />
        <parent link="left_s2" />
        <child link="left_s3" />
        <limit effort="87.0" velocity="30.0" lower="-3.1416" upper="0.3491" />
    </joint>
    <joint name="left_s3_0" type="revolute">
        <origin xyz="-3.88578e-16 0.04475 -0.07335" rpy="5.06891e-29 6.12323e-17 -7.93161e-15" />
        <axis xyz="0 0 1" />
        <parent link="left_s3" />
        <child link="left_e1" />
        <limit effort="87.0" velocity="30.0" lower="-2.3562" upper="2.3562" />
    </joint>
    <joint name="left_w1_0" type="revolute">
        <origin xyz="-8.32667e-17 -0.0285 -0.13567" rpy="-4.2466e-15 1.76757e-14 2.71935e-15" />
        <axis xyz="0 -1 0" />
        <parent link="left_w0" />
        <child link="left_w1" />
        <limit effort="87.0" velocity="30.0" lower="-1.5708" upper="1.5708" />
    </joint>
    <joint name="left_w2_0" type="revolute">
        <origin xyz="0.0285 0.0285 -0.057" rpy="-2.21714e-14 1.79213e-44 1.61661e-30" />
        <axis xyz="-1 0 0" />
        <parent link="left_w1" />
        <child link="left_w2" />
        <limit effort="87.0" velocity="30.0" lower="-1.5708" upper="1.5708" />
    </joint>
    <joint name="right_e1_0" type="revolute">
        <origin xyz="-0.04229 1.60479e-17 -0.289385" rpy="-6.12323e-17 6.12323e-17 -6.12323e-17" />
        <axis xyz="1 0 2.98117e-16" />
        <parent link="right_e1" />
        <child link="right_e2" />
        <limit effort="87.0" velocity="30.0" lower="-2.618" upper="0.0" />
    </joint>
    <joint name="right_e2_0" type="revolute">
        <origin xyz="0.04229 -3.11655e-17 -0.12429" rpy="1.61476e-27 -7.92016e-28 -3.14159" />
        <axis xyz="0 0 1" />
        <parent link="right_e2" />
        <child link="right_w0" />
        <limit effort="87.0" velocity="30.0" lower="-2.3562" upper="2.3562" />
    </joint>
    <joint name="right_s1_0" type="revolute">
        <origin xyz="-0.151213 0.0137132 -0.06" rpy="-2.27247e-31 -2.31296e-16 7.35455e-16" />
        <axis xyz="1 0 0" />
        <parent link="s1" />
        <child link="right_s2" />
        <limit effort="87.0" velocity="30.0" lower="-3.1416" upper="1.5708" />
    </joint>
    <joint name="right_s2_0" type="revolute">
        <origin xyz="-0.06958 -0.04475 4.44089e-16" rpy="-5.61996e-30 -1.32163e-14 -3.9443e-31" />
        <axis xyz="0 1 0" />
        <parent link="right_s2" />
        <child link="right_s3" />
        <limit effort="87.0" velocity="30.0" lower="-0.3491" upper="3.1416" />
    </joint>
    <joint name="right_s3_0" type="revolute">
        <origin xyz="4.16334e-16 0.04475 -0.07335" rpy="-2.235e-28 1.07364e-27 -3.41903e-14" />
        <axis xyz="0 0 1" />
        <parent link="right_s3" />
        <child link="right_e1" />
        <limit effort="87.0" velocity="30.0" lower="-2.3562" upper="2.3562" />
    </joint>
    <joint name="right_w1_0" type="revolute">
        <origin xyz="1.66533e-16 0.0285 -0.13567" rpy="9.03554e-29 -4.3255e-14 -4.98658e-30" />
        <axis xyz="0 1 0" />
        <parent link="right_w0" />
        <child link="right_w1" />
        <limit effort="87.0" velocity="30.0" lower="-1.5708" upper="1.5708" />
    </joint>
    <joint name="right_w2_0" type="revolute">
        <origin xyz="0.0285 -0.0285 -0.057" rpy="-8.07794e-27 1.05707e-27 -3.14159" />
        <axis xyz="1 0 0" />
        <parent link="right_w1" />
        <child link="right_w2" />
        <limit effort="87.0" velocity="30.0" lower="-1.5708" upper="1.5708" />
    </joint>
    <!-- Actuated grippers: EE/control frame (*_gripper) aligned with *_w2 so the teleop controller axes are preserved; the rotated gripper body + prismatic fingers hang off it via *_gripper_body_0. -->
    <link name="left_gripper">
        <inertial>
            <mass value="0.001" />
            <origin xyz="0 0 0" rpy="0 -0 0" />
            <inertia ixx="1e-06" ixy="0" ixz="0" iyy="1e-06" iyz="0" izz="1e-06" />
        </inertial>
    </link>
    <link name="left_gripper_body">
        <inertial>
            <mass value="0.001" />
            <origin xyz="0 0 0" rpy="0 -0 0" />
            <inertia ixx="1e-06" ixy="0" ixz="0" iyy="1e-06" iyz="0" izz="1e-06" />
        </inertial>
        <visual>
            <origin xyz="1.05098e-15 0.110598 -0.164102" rpy="0 -0 0" />
            <geometry>
                <mesh filename="package://axol_kit/meshes/Gripper_Base.stl" scale="1 1 1" />
            </geometry>
            <material name="0.600000_0.600000_0.600000_0.000000_0.000000">
                <color rgba="0.6 0.6 0.6 1" />
            </material>
        </visual>
        <collision>
            <origin xyz="1.05098e-15 0.110598 -0.164102" rpy="0 -0 0" />
            <geometry>
                <mesh filename="package://axol_kit/meshes/Gripper_Base.stl" scale="1 1 1" />
            </geometry>
        </collision>
    </link>
    <link name="left_gripper_finger_a">
        <inertial>
            <mass value="0.001" />
            <origin xyz="0 0 0" rpy="0 -0 0" />
            <inertia ixx="1e-06" ixy="0" ixz="0" iyy="1e-06" iyz="0" izz="1e-06" />
        </inertial>
        <visual>
            <origin xyz="0.0125619 0.161598 -0.198102" rpy="0 -0 0" />
            <geometry>
                <mesh filename="package://axol_kit/meshes/Gripper_Tip.stl" scale="1 1 1" />
            </geometry>
            <material name="0.600000_0.600000_0.600000_0.000000_0.000000">
                <color rgba="0.6 0.6 0.6 1" />
            </material>
        </visual>
        <collision>
            <origin xyz="0.0125619 0.161598 -0.198102" rpy="0 -0 0" />
            <geometry>
                <mesh filename="package://axol_kit/meshes/Gripper_Tip.stl" scale="1 1 1" />
            </geometry>
        </collision>
    </link>
    <link name="left_gripper_finger_b">
        <inertial>
            <mass value="0.001" />
            <origin xyz="0 0 0" rpy="0 -0 0" />
            <inertia ixx="1e-06" ixy="0" ixz="0" iyy="1e-06" iyz="0" izz="1e-06" />
        </inertial>
        <visual>
            <origin xyz="0.0125619 0.161598 -0.196602" rpy="0 -0 0" />
            <geometry>
                <mesh filename="package://axol_kit/meshes/Gripper_Tip.stl" scale="1 1 1" />
            </geometry>
            <material name="0.600000_0.600000_0.600000_0.000000_0.000000">
                <color rgba="0.6 0.6 0.6 1" />
            </material>
        </visual>
        <collision>
            <origin xyz="0.0125619 0.161598 -0.196602" rpy="0 -0 0" />
            <geometry>
                <mesh filename="package://axol_kit/meshes/Gripper_Tip.stl" scale="1 1 1" />
            </geometry>
        </collision>
    </link>
    <link name="right_gripper">
        <inertial>
            <mass value="0.001" />
            <origin xyz="0 0 0" rpy="0 -0 0" />
            <inertia ixx="1e-06" ixy="0" ixz="0" iyy="1e-06" iyz="0" izz="1e-06" />
        </inertial>
    </link>
    <link name="right_gripper_body">
        <inertial>
            <mass value="0.001" />
            <origin xyz="0 0 0" rpy="0 -0 0" />
            <inertia ixx="1e-06" ixy="0" ixz="0" iyy="1e-06" iyz="0" izz="1e-06" />
        </inertial>
        <visual>
            <origin xyz="1.05098e-15 0.110598 -0.164102" rpy="0 -0 0" />
            <geometry>
                <mesh filename="package://axol_kit/meshes/Gripper_Base.stl" scale="1 1 1" />
            </geometry>
            <material name="0.600000_0.600000_0.600000_0.000000_0.000000">
                <color rgba="0.6 0.6 0.6 1" />
            </material>
        </visual>
        <collision>
            <origin xyz="1.05098e-15 0.110598 -0.164102" rpy="0 -0 0" />
            <geometry>
                <mesh filename="package://axol_kit/meshes/Gripper_Base.stl" scale="1 1 1" />
            </geometry>
        </collision>
    </link>
    <link name="right_gripper_finger_a">
        <inertial>
            <mass value="0.001" />
            <origin xyz="0 0 0" rpy="0 -0 0" />
            <inertia ixx="1e-06" ixy="0" ixz="0" iyy="1e-06" iyz="0" izz="1e-06" />
        </inertial>
        <visual>
            <origin xyz="0.0125619 0.161598 -0.198102" rpy="0 -0 0" />
            <geometry>
                <mesh filename="package://axol_kit/meshes/Gripper_Tip.stl" scale="1 1 1" />
            </geometry>
            <material name="0.600000_0.600000_0.600000_0.000000_0.000000">
                <color rgba="0.6 0.6 0.6 1" />
            </material>
        </visual>
        <collision>
            <origin xyz="0.0125619 0.161598 -0.198102" rpy="0 -0 0" />
            <geometry>
                <mesh filename="package://axol_kit/meshes/Gripper_Tip.stl" scale="1 1 1" />
            </geometry>
        </collision>
    </link>
    <link name="right_gripper_finger_b">
        <inertial>
            <mass value="0.001" />
            <origin xyz="0 0 0" rpy="0 -0 0" />
            <inertia ixx="1e-06" ixy="0" ixz="0" iyy="1e-06" iyz="0" izz="1e-06" />
        </inertial>
        <visual>
            <origin xyz="0.0125619 0.161598 -0.196602" rpy="0 -0 0" />
            <geometry>
                <mesh filename="package://axol_kit/meshes/Gripper_Tip.stl" scale="1 1 1" />
            </geometry>
            <material name="0.600000_0.600000_0.600000_0.000000_0.000000">
                <color rgba="0.6 0.6 0.6 1" />
            </material>
        </visual>
        <collision>
            <origin xyz="0.0125619 0.161598 -0.196602" rpy="0 -0 0" />
            <geometry>
                <mesh filename="package://axol_kit/meshes/Gripper_Tip.stl" scale="1 1 1" />
            </geometry>
        </collision>
    </link>
    <joint name="left_gripper_0" type="fixed">
        <origin xyz="-0.0285 -2.55776e-17 -0.032251" rpy="0 0 0" />
        <axis xyz="0 0 1" />
        <parent link="left_w2" />
        <child link="left_gripper" />
    </joint>
    <joint name="left_gripper_body_0" type="fixed">
        <origin xyz="0 0 0" rpy="1.5708 0 0" />
        <axis xyz="0 0 1" />
        <parent link="left_gripper" />
        <child link="left_gripper_body" />
    </joint>
    <joint name="left_gripper_joint_a" type="prismatic">
        <origin xyz="0.01256 -0.0508 -0.034" rpy="3.14159 -1.0297e-14 3.14159" />
        <axis xyz="1 -8.38667e-15 1.67733e-14" />
        <parent link="left_gripper_body" />
        <child link="left_gripper_finger_a" />
        <limit lower="0.0" upper="0.058804" velocity="1.0" effort="20.0" />
    </joint>
    <joint name="left_gripper_joint_b" type="prismatic">
        <origin xyz="-0.01256 -0.0508 0.0325" rpy="0 1.12222e-14 -2.71556e-15" />
        <axis xyz="1 -8.38667e-15 1.67733e-14" />
        <parent link="left_gripper_body" />
        <child link="left_gripper_finger_b" />
        <limit lower="0.0" upper="0.058804" velocity="1.0" effort="20.0" />
        <mimic joint="left_gripper_joint_a" multiplier="1.0" offset="0.0" />
    </joint>
    <joint name="right_gripper_0" type="fixed">
        <origin xyz="0.0285 -1.5279e-17 -0.032251" rpy="0 0 0" />
        <axis xyz="0 0 1" />
        <parent link="right_w2" />
        <child link="right_gripper" />
    </joint>
    <joint name="right_gripper_body_0" type="fixed">
        <origin xyz="0 0 0" rpy="1.5708 0 0" />
        <axis xyz="0 0 1" />
        <parent link="right_gripper" />
        <child link="right_gripper_body" />
    </joint>
    <joint name="right_gripper_joint_a" type="prismatic">
        <origin xyz="0.01256 -0.0508 -0.034" rpy="3.14159 -1.0297e-14 3.14159" />
        <axis xyz="1 -8.38667e-15 1.67733e-14" />
        <parent link="right_gripper_body" />
        <child link="right_gripper_finger_a" />
        <limit lower="0.0" upper="0.058804" velocity="1.0" effort="20.0" />
    </joint>
    <joint name="right_gripper_joint_b" type="prismatic">
        <origin xyz="-0.01256 -0.0508 0.0325" rpy="0 1.12222e-14 -2.71556e-15" />
        <axis xyz="1 -8.38667e-15 1.67733e-14" />
        <parent link="right_gripper_body" />
        <child link="right_gripper_finger_b" />
        <limit lower="0.0" upper="0.058804" velocity="1.0" effort="20.0" />
        <mimic joint="right_gripper_joint_a" multiplier="1.0" offset="0.0" />
    </joint>
</robot>
